Workbook

Sheet Palinsesto
B2: =IFERROR(MATCH($D$2,Partite!F1:F3000,0)-1,"Non ci sono Partite") -> 1076 | C2: Data | D2: =TODAY()+1 -> 46227
C4: Campionato | D4: Giornata | E4: Data | F4: Ora | G4: Squadra | H4: V | I4: P | J4: S | K4: GF | L4: GS | M4: Diff. Reti | N4: Punti | O4: Pos. | P4: Forma1 | Q4: Forma2 | R4: Forma3 | S4: Forma4 | T4: Forma5 | U4: % | V4: Diff. | W4: 12+U 4,5 | X4: % | Y4: Multigol | Z4: % | AA4: Over 1,5 | AB4: % | AC4: 0-2 | AD4: 1-3 | AE4: 2-5
B6: 1 | C6: =VLOOKUP($B$2+B6,Partite!$A$1:$AE$3000,2,FALSE) -> Allsvenskan | D6: =VLOOKUP($B$2+B6,Partite!$A$1:$AE$3000,4,FALSE) -> 14 | E6: =VLOOKUP($B$2+B6,Partite!$A$1:$AE$3000,6,FALSE) -> 46227 | F6: =VLOOKUP($B$2+B6,Partite!$A$1:$AE$3000,7,FALSE) -> 19:00 | G6: =VLOOKUP($B$2+B6,Partite!$A$1:$AE$3000,8,FALSE) -> Västerås | H6: =IFERROR(VLOOKUP(G6,Classifica!$C$2:$R$131,3,FALSE),"") -> 5 | I6: =IFERROR(VLOOKUP(G6,Classifica!$C$2:$R$131,4,FALSE),"") -> 4 | J6: =IFERROR(VLOOKUP(G6,Classifica!$C$2:$R$131,5,FALSE),"") -> 4 | K6: =IFERROR(VLOOKUP(G6,Classifica!$C$2:$R$131,6,FALSE),"") -> 22 | L6: =IFERROR(VLOOKUP(G6,Classifica!$C$2:$R$131,7,FALSE),"") -> 23 | M6: =IFERROR(VLOOKUP(G6,Classifica!$C$2:$R$131,8,FALSE),"") -> -1 | N6: =IFERROR(VLOOKUP(G6,Classifica!$C$2:$R$131,9,FALSE),"") -> 19 | O6: =IFERROR(VLOOKUP(G6,Classifica!$C$2:$R$131,16,FALSE),"") -> 8 | P6: =IFERROR(MID(INDEX(Classifica!M:M, MATCH(G6, Classifica!C:C, 0)), 1, 1), "") -> W | Q6: =IFERROR(MID(INDEX(Classifica!M:M, MATCH(G6, Classifica!C:C, 0)), 3, 1), "") -> L | R6: =IFERROR(MID(INDEX(Classifica!M:M, MATCH(G6, Classifica!C:C, 0)), 5, 1), "") -> W | S6: =IFERROR(MID(INDEX(Classifica!M:M, MATCH(G6, Classifica!C:C, 0)), 7, 1), "") -> W | T6: =IFERROR(MID(INDEX(Classifica!M:M, MATCH(G6, Classifica!C:C, 0)), 9, 1), "") -> D | U6: =IFERROR(IF(P6="","",COUNTIF(P6:T6,"W")*20+COUNTIF(P6:T6,"D")*7),"") -> 67 | V6: =IFERROR(ABS(U6-U7),"") -> 40 | W6: =COUNTIFS(Partite!$V:$V,1,Partite!$H:$H,Palinsesto!G6)+COUNTIFS(Partite!$V:$V,1,Partite!$J:$J,Palinsesto!G6) -> 6 | X6: =IFERROR(AVERAGE(IFERROR(INT(W6/(SUM(H6:J6))*100),""),IFERROR(INT(W7/(SUM(H7:J7))*100),"")),"") -> 48 | Y6: =INDEX(AC$4:AE$4, MATCH(MAX(AC6:AE6), AC6:AE6, 0)) -> 0-2 | Z6: =IFERROR(INT((LARGE(AC6:AE6,1)/SUM(H6:J6))*100),"") -> 69 | AA6: =COUNTIFS(Partite!$W:$W,1,Partite!$H:$H,Palinsesto!G6)+COUNTIFS(Partite!$W:$W,1,Partite!$J:$J,Palinsesto!G6) -> 10 | AB6: =IFERROR(INT(AVERAGE(AA6/(SUM(H6:J6))*100,(AA7/(SUM(H7:J7))*100))),"") -> 88 | AC6: =COUNTIFS(Partite!$X:$X,1,Partite!$H:$H,Palinsesto!G6)+COUNTIFS(Partite!$X:$X,1,Partite!$J:$J,Palinsesto!G6) -> 9 | AD6: =COUNTIFS(Partite!$Y:$Y,1,Partite!$H:$H,Palinsesto!G6)+COUNTIFS(Partite!$Y:$Y,1,Partite!$J:$J,Palinsesto!G6) -> 8 | AE6: =COUNTIFS(Partite!$Z:$Z,1,Partite!$H:$H,Palinsesto!G6)+COUNTIFS(Partite!$Z:$Z,1,Partite!$J:$J,Palinsesto!G6) -> 7
G7: =VLOOKUP($B$2+B6,Partite!$A$1:$AE$3000,10,FALSE) -> Örgryte | H7: =IFERROR(VLOOKUP(G7,Classifica!$C$2:$R$131,3,FALSE),"") -> 2 | I7: =IFERROR(VLOOKUP(G7,Classifica!$C$2:$R$131,4,FALSE),"") -> 3 | J7: =IFERROR(VLOOKUP(G7,Classifica!$C$2:$R$131,5,FALSE),"") -> 7 | K7: =IFERROR(VLOOKUP(G7,Classifica!$C$2:$R$131,6,FALSE),"") -> 14 | L7: =IFERROR(VLOOKUP(G7,Classifica!$C$2:$R$131,7,FALSE),"") -> 31 | M7: =IFERROR(VLOOKUP(G7,Classifica!$C$2:$R$131,8,FALSE),"") -> -17 | N7: =IFERROR(VLOOKUP(G7,Classifica!$C$2:$R$131,9,FALSE),"") -> 9 | O7: =IFERROR(VLOOKUP(G7,Classifica!$C$2:$R$131,16,FALSE),"") -> 15 | P7: =IFERROR(MID(INDEX(Classifica!M:M, MATCH(G7, Classifica!C:C, 0)), 1, 1), "") -> L | Q7: =IFERROR(MID(INDEX(Classifica!M:M, MATCH(G7, Classifica!C:C, 0)), 3, 1), "") -> L | R7: =IFERROR(MID(INDEX(Classifica!M:M, MATCH(G7, Classifica!C:C, 0)), 5, 1), "") -> D | S7: =IFERROR(MID(INDEX(Classifica!M:M, MATCH(G7, Classifica!C:C, 0)), 7, 1), "") -> L | T7: =IFERROR(MID(INDEX(Classifica!M:M, MATCH(G7, Classifica!C:C, 0)), 9, 1), "") -> W | U7: =IFERROR(IF(P7="","",COUNTIF(P7:T7,"W")*20+COUNTIF(P7:T7,"D")*7),"") -> 27 | W7: =COUNTIFS(Partite!$V:$V,1,Partite!$H:$H,Palinsesto!G7)+COUNTIFS(Partite!$V:$V,1,Partite!$J:$J,Palinsesto!G7) -> 6 | Y7: =INDEX(AC$4:AE$4, MATCH(MAX(AC7:AE7), AC7:AE7, 0)) -> 0-2 | Z7: =IFERROR(INT((LARGE(AC7:AE7,1)/SUM(H7:J7))*100),"") -> 75 | AA7: =COUNTIFS(Partite!$W:$W,1,Partite!$H:$H,Palinsesto!G7)+COUNTIFS(Partite!$W:$W,1,Partite!$J:$J,Palinsesto!G7) -> 12 | AC7: =COUNTIFS(Partite!$X:$X,1,Partite!$H:$H,Palinsesto!G7)+COUNTIFS(Partite!$X:$X,1,Partite!$J:$J,Palinsesto!G7) -> 9 | AD7: =COUNTIFS(Partite!$Y:$Y,1,Partite!$H:$H,Palinsesto!G7)+COUNTIFS(Partite!$Y:$Y,1,Partite!$J:$J,Palinsesto!G7) -> 8 | AE7: =COUNTIFS(Partite!$Z:$Z,1,Partite!$H:$H,Palinsesto!G7)+COUNTIFS(Partite!$Z:$Z,1,Partite!$J:$J,Palinsesto!G7) -> 7
B9: =B6+1 -> 2 | C9: =VLOOKUP($B$2+B9,Partite!$A$1:$AE$3000,2,FALSE) -> Danish | D9: =VLOOKUP($B$2+B9,Partite!$A$1:$AE$3000,4,FALSE) -> 1 | E9: =VLOOKUP($B$2+B9,Partite!$A$1:$AE$3000,6,FALSE) -> 46227 | F9: =VLOOKUP($B$2+B9,Partite!$A$1:$AE$3000,7,FALSE) -> 19:00 | G9: =VLOOKUP($B$2+B9,Partite!$A$1:$AE$3000,8,FALSE) -> Viborg | H9: =IFERROR(VLOOKUP(G9,Classifica!$C$2:$R$131,3,FALSE),"") -> 0 | I9: =IFERROR(VLOOKUP(G9,Classifica!$C$2:$R$131,4,FALSE),"") -> 0 | J9: =IFERROR(VLOOKUP(G9,Classifica!$C$2:$R$131,5,FALSE),"") -> 0 | K9: =IFERROR(VLOOKUP(G9,Classifica!$C$2:$R$131,6,FALSE),"") -> 0 | L9: =IFERROR(VLOOKUP(G9,Classifica!$C$2:$R$131,7,FALSE),"") -> 0 | M9: =IFERROR(VLOOKUP(G9,Classifica!$C$2:$R$131,8,FALSE),"") -> 0 | N9: =IFERROR(VLOOKUP(G9,Classifica!$C$2:$R$131,9,FALSE),"") -> 0 | O9: =IFERROR(VLOOKUP(G9,Classifica!$C$2:$R$131,16,FALSE),"") -> 2 | P9: =IFERROR(MID(INDEX(Classifica!M:M, MATCH(G9, Classifica!C:C, 0)), 1, 1), "") | Q9: =IFERROR(MID(INDEX(Classifica!M:M, MATCH(G9, Classifica!C:C, 0)), 3, 1), "") | R9: =IFERROR(MID(INDEX(Classifica!M:M, MATCH(G9, Classifica!C:C, 0)), 5, 1), "") | S9: =IFERROR(MID(INDEX(Classifica!M:M, MATCH(G9, Classifica!C:C, 0)), 7, 1), "") | T9: =IFERROR(MID(INDEX(Classifica!M:M, MATCH(G9, Classifica!C:C, 0)), 9, 1), "") | U9: =IFERROR(IF(P9="","",COUNTIF(P9:T9,"W")*20+COUNTIF(P9:T9,"D")*7),"") | V9: =IFERROR(ABS(U9-U10),"") | W9: =COUNTIFS(Partite!$V:$V,1,Partite!$H:$H,Palinsesto!G9)+COUNTIFS(Partite!$V:$V,1,Partite!$J:$J,Palinsesto!G9) -> 0 | X9: =IFERROR(AVERAGE(IFERROR(INT(W9/(SUM(H9:J9))*100),""),IFERROR(INT(W10/(SUM(H10:J10))*100),"")),"") | Y9: =INDEX(AC$4:AE$4, MATCH(MAX(AC9:AE9), AC9:AE9, 0)) -> 0-2 | Z9: =IFERROR(INT((LARGE(AC9:AE9,1)/SUM(H9:J9))*100),"") | AA9: =COUNTIFS(Partite!$W:$W,1,Partite!$H:$H,Palinsesto!G9)+COUNTIFS(Partite!$W:$W,1,Partite!$J:$J,Palinsesto!G9) -> 0 | AB9: =IFERROR(INT(AVERAGE(AA9/(SUM(H9:J9))*100,(AA10/(SUM(H10:J10))*100))),"") | AC9: =COUNTIFS(Partite!$X:$X,1,Partite!$H:$H,Palinsesto!G9)+COUNTIFS(Partite!$X:$X,1,Partite!$J:$J,Palinsesto!G9) -> 0 | AD9: =COUNTIFS(Partite!$Y:$Y,1,Partite!$H:$H,Palinsesto!G9)+COUNTIFS(Partite!$Y:$Y,1,Partite!$J:$J,Palinsesto!G9) -> 0 | AE9: =COUNTIFS(Partite!$Z:$Z,1,Partite!$H:$H,Palinsesto!G9)+COUNTIFS(Partite!$Z:$Z,1,Partite!$J:$J,Palinsesto!G9) -> 0
G10: =VLOOKUP($B$2+B9,Partite!$A$1:$AE$3000,10,FALSE) -> Odense | H10: =IFERROR(VLOOKUP(G10,Classifica!$C$2:$R$131,3,FALSE),"") -> 0 | I10: =IFERROR(VLOOKUP(G10,Classifica!$C$2:$R$131,4,FALSE),"") -> 0 | J10: =IFERROR(VLOOKUP(G10,Classifica!$C$2:$R$131,5,FALSE),"") -> 0 | K10: =IFERROR(VLOOKUP(G10,Classifica!$C$2:$R$131,6,FALSE),"") -> 0 | L10: =IFERROR(VLOOKUP(G10,Classifica!$C$2:$R$131,7,FALSE),"") -> 0 | M10: =IFERROR(VLOOKUP(G10,Classifica!$C$2:$R$131,8,FALSE),"") -> 0 | N10: =IFERROR(VLOOKUP(G10,Classifica!$C$2:$R$131,9,FALSE),"") -> 0 | O10: =IFERROR(VLOOKUP(G10,Classifica!$C$2:$R$131,16,FALSE),"") -> 8 | P10: =IFERROR(MID(INDEX(Classifica!M:M, MATCH(G10, Classifica!C:C, 0)), 1, 1), "") | Q10: =IFERROR(MID(INDEX(Classifica!M:M, MATCH(G10, Classifica!C:C, 0)), 3, 1), "") | R10: =IFERROR(MID(INDEX(Classifica!M:M, MATCH(G10, Classifica!C:C, 0)), 5, 1), "") | S10: =IFERROR(MID(INDEX(Classifica!M:M, MATCH(G10, Classifica!C:C, 0)), 7, 1), "") | T10: =IFERROR(MID(INDEX(Classifica!M:M, MATCH(G10, Classifica!C:C, 0)), 9, 1), "") | U10: =IFERROR(IF(P10="","",COUNTIF(P10:T10,"W")*20+COUNTIF(P10:T10,"D")*7),"") | W10: =COUNTIFS(Partite!$V:$V,1,Partite!$H:$H,Palinsesto!G10)+COUNTIFS(Partite!$V:$V,1,Partite!$J:$J,Palinsesto!G10) -> 0 | Y10: =INDEX(AC$4:AE$4, MATCH(MAX(AC10:AE10), AC10:AE10, 0)) -> 0-2 | Z10: =IFERROR(INT((LARGE(AC10:AE10,1)/SUM(H10:J10))*100),"") | AA10: =COUNTIFS(Partite!$W:$W,1,Partite!$H:$H,Palinsesto!G10)+COUNTIFS(Partite!$W:$W,1,Partite!$J:$J,Palinsesto!G10) -> 0 | AC10: =COUNTIFS(Partite!$X:$X,1,Partite!$H:$H,Palinsesto!G10)+COUNTIFS(Partite!$X:$X,1,Partite!$J:$J,Palinsesto!G10) -> 0 | AD10: =COUNTIFS(Partite!$Y:$Y,1,Partite!$H:$H,Palinsesto!G10)+COUNTIFS(Partite!$Y:$Y,1,Partite!$J:$J,Palinsesto!G10) -> 0 | AE10: =COUNTIFS(Partite!$Z:$Z,1,Partite!$H:$H,Palinsesto!G10)+COUNTIFS(Partite!$Z:$Z,1,Partite!$J:$J,Palinsesto!G10) -> 0
B12: =B9+1 -> 3 | C12: =VLOOKUP($B$2+B12,Partite!$A$1:$AE$3000,2,FALSE) -> Ireland | D12: =VLOOKUP($B$2+B12,Partite!$A$1:$AE$3000,4,FALSE) -> 25 | E12: =VLOOKUP($B$2+B12,Partite!$A$1:$AE$3000,6,FALSE) -> 46227 | F12: =VLOOKUP($B$2+B12,Partite!$A$1:$AE$3000,7,FALSE) -> 20:00 (21:00) | G12: =VLOOKUP($B$2+B12,Partite!$A$1:$AE$3000,8,FALSE) -> St Patrick's | H12: =IFERROR(VLOOKUP(G12,Classifica!$C$2:$R$131,3,FALSE),"") -> 12 | I12: =IFERROR(VLOOKUP(G12,Classifica!$C$2:$R$131,4,FALSE),"") -> 6 | J12: =IFERROR(VLOOKUP(G12,Classifica!$C$2:$R$131,5,FALSE),"") -> 6 | K12: =IFERROR(VLOOKUP(G12,Classifica!$C$2:$R$131,6,FALSE),"") -> 39 | L12: =IFERROR(VLOOKUP(G12,Classifica!$C$2:$R$131,7,FALSE),"") -> 20 | M12: =IFERROR(VLOOKUP(G12,Classifica!$C$2:$R$131,8,FALSE),"") -> 19 | N12: =IFERROR(VLOOKUP(G12,Classifica!$C$2:$R$131,9,FALSE),"") -> 42 | O12: =IFERROR(VLOOKUP(G12,Classifica!$C$2:$R$131,16,FALSE),"") -> 3 | P12: =IFERROR(MID(INDEX(Classifica!M:M, MATCH(G12, Classifica!C:C, 0)), 1, 1), "") -> W | Q12: =IFERROR(MID(INDEX(Classifica!M:M, MATCH(G12, Classifica!C:C, 0)), 3, 1), "") -> W | R12: =IFERROR(MID(INDEX(Classifica!M:M, MATCH(G12, Classifica!C:C, 0)), 5, 1), "") -> L | S12: =IFERROR(MID(INDEX(Classifica!M:M, MATCH(G12, Classifica!C:C, 0)), 7, 1), "") -> W | T12: =IFERROR(MID(INDEX(Classifica!M:M, MATCH(G12, Classifica!C:C, 0)), 9, 1), "") -> D | U12: =IFERROR(IF(P12="","",COUNTIF(P12:T12,"W")*20+COUNTIF(P12:T12,"D")*7),"") -> 67 | V12: =IFERROR(ABS(U12-U13),"") -> 27 | W12: =COUNTIFS(Partite!$V:$V,1,Partite!$H:$H,Palinsesto!G12)+COUNTIFS(Partite!$V:$V,1,Partite!$J:$J,Palinsesto!G12) -> 14 | X12: =IFERROR(AVERAGE(IFERROR(INT(W12/(SUM(H12:J12))*100),""),IFERROR(INT(W13/(SUM(H13:J13))*100),"")),"") -> 56 | Y12: =INDEX(AC$4:AE$4, MATCH(MAX(AC12:AE12), AC12:AE12, 0)) -> 0-2 | Z12: =IFERROR(INT((LARGE(AC12:AE12,1)/SUM(H12:J12))*100),"") -> 75 | AA12: =COUNTIFS(Partite!$W:$W,1,Partite!$H:$H,Palinsesto!G12)+COUNTIFS(Partite!$W:$W,1,Partite!$J:$J,Palinsesto!G12) -> 17 | AB12: =IFERROR(INT(AVERAGE(AA12/(SUM(H12:J12))*100,(AA13/(SUM(H13:J13))*100))),"") -> 79 | AC12: =COUNTIFS(Partite!$X:$X,1,Partite!$H:$H,Palinsesto!G12)+COUNTIFS(Partite!$X:$X,1,Partite!$J:$J,Palinsesto!G12) -> 18 | AD12: =COUNTIFS(Partite!$Y:$Y,1,Partite!$H:$H,Palinsesto!G12)+COUNTIFS(Partite!$Y:$Y,1,Partite!$J:$J,Palinsesto!G12) -> 14 | AE12: =COUNTIFS(Partite!$Z:$Z,1,Partite!$H:$H,Palinsesto!G12)+COUNTIFS(Partite!$Z:$Z,1,Partite!$J:$J,Palinsesto!G12) -> 13
G13: =VLOOKUP($B$2+B12,Partite!$A$1:$AE$3000,10,FALSE) -> Dundalk FC | H13: =IFERROR(VLOOKUP(G13,Classifica!$C$2:$R$131,3,FALSE),"") -> 9 | I13: =IFERROR(VLOOKUP(G13,Classifica!$C$2:$R$131,4,FALSE),"") -> 8 | J13: =IFERROR(VLOOKUP(G13,Classifica!$C$2:$R$131,5,FALSE),"") -> 7 | K13: =IFERROR(VLOOKUP(G13,Classifica!$C$2:$R$131,6,FALSE),"") -> 38 | L13: =IFERROR(VLOOKUP(G13,Classifica!$C$2:$R$131,7,FALSE),"") -> 36 | M13: =IFERROR(VLOOKUP(G13,Classifica!$C$2:$R$131,8,FALSE),"") -> 2 | N13: =IFERROR(VLOOKUP(G13,Classifica!$C$2:$R$131,9,FALSE),"") -> 35 | O13: =IFERROR(VLOOKUP(G13,Classifica!$C$2:$R$131,16,FALSE),"") -> 4 | P13: =IFERROR(MID(INDEX(Classifica!M:M, MATCH(G13, Classifica!C:C, 0)), 1, 1), "") -> W | Q13: =IFERROR(MID(INDEX(Classifica!M:M, MATCH(G13, Classifica!C:C, 0)), 3, 1), "") -> W | R13: =IFERROR(MID(INDEX(Classifica!M:M, MATCH(G13, Classifica!C:C, 0)), 5, 1), "") -> L | S13: =IFERROR(MID(INDEX(Classifica!M:M, MATCH(G13, Classifica!C:C, 0)), 7, 1), "") -> L | T13: =IFERROR(MID(INDEX(Classifica!M:M, MATCH(G13, Classifica!C:C, 0)), 9, 1), "") -> L | U13: =IFERROR(IF(P13="","",COUNTIF(P13:T13,"W")*20+COUNTIF(P13:T13,"D")*7),"") -> 40 | W13: =COUNTIFS(Partite!$V:$V,1,Partite!$H:$H,Palinsesto!G13)+COUNTIFS(Partite!$V:$V,1,Partite!$J:$J,Palinsesto!G13) -> 13 | Y13: =INDEX(AC$4:AE$4, MATCH(MAX(AC13:AE13), AC13:AE13, 0)) -> 0-2 | Z13: =IFERROR(INT((LARGE(AC13:AE13,1)/SUM(H13:J13))*100),"") -> 87 | AA13: =COUNTIFS(Partite!$W:$W,1,Partite!$H:$H,Palinsesto!G13)+COUNTIFS(Partite!$W:$W,1,Partite!$J:$J,Palinsesto!G13) -> 21 | AC13: =COUNTIFS(Partite!$X:$X,1,Partite!$H:$H,Palinsesto!G13)+COUNTIFS(Partite!$X:$X,1,Partite!$J:$J,Palinsesto!G13) -> 21 | AD13: =COUNTIFS(Partite!$Y:$Y,1,Partite!$H:$H,Palinsesto!G13)+COUNTIFS(Partite!$Y:$Y,1,Partite!$J:$J,Palinsesto!G13) -> 21 | AE13: =COUNTIFS(Partite!$Z:$Z,1,Partite!$H:$H,Palinsesto!G13)+COUNTIFS(Partite!$Z:$Z,1,Partite!$J:$J,Palinsesto!G13) -> 13
B15: =B12+1 -> 4 | C15: =VLOOKUP($B$2+B15,Partite!$A$1:$AE$3000,2,FALSE) -> Veikkausliiga | D15: =VLOOKUP($B$2+B15,Partite!$A$1:$AE$3000,4,FALSE) -> 17 | E15: =VLOOKUP($B$2+B15,Partite!$A$1:$AE$3000,6,FALSE) -> 46227 | F15: =VLOOKUP($B$2+B15,Partite!$A$1:$AE$3000,7,FALSE) -> 19:00 (18:00) | G15: =VLOOKUP($B$2+B15,Partite!$A$1:$AE$3000,8,FALSE) -> FF Jaro | H15: =IFERROR(VLOOKUP(G15,Classifica!$C$2:$R$131,3,FALSE),"") -> 2 | I15: =IFERROR(VLOOKUP(G15,Classifica!$C$2:$R$131,4,FALSE),"") -> 5 | J15: =IFERROR(VLOOKUP(G15,Classifica!$C$2:$R$131,5,FALSE),"") -> 8 | K15: =IFERROR(VLOOKUP(G15,Classifica!$C$2:$R$131,6,FALSE),"") -> 15 | L15: =IFERROR(VLOOKUP(G15,Classifica!$C$2:$R$131,7,FALSE),"") -> 32 | M15: =IFERROR(VLOOKUP(G15,Classifica!$C$2:$R$131,8,FALSE),"") -> -17 | N15: =IFERROR(VLOOKUP(G15,Classifica!$C$2:$R$131,9,FALSE),"") -> 11 | O15: =IFERROR(VLOOKUP(G15,Classifica!$C$2:$R$131,16,FALSE),"") -> 11 | P15: =IFERROR(MID(INDEX(Classifica!M:M, MATCH(G15, Classifica!C:C, 0)), 1, 1), "") -> L | Q15: =IFERROR(MID(INDEX(Classifica!M:M, MATCH(G15, Classifica!C:C, 0)), 3, 1), "") -> L | R15: =IFERROR(MID(INDEX(Classifica!M:M, MATCH(G15, Classifica!C:C, 0)), 5, 1), "") -> D | S15: =IFERROR(MID(INDEX(Classifica!M:M, MATCH(G15, Classifica!C:C, 0)), 7, 1), "") -> L | T15: =IFERROR(MID(INDEX(Classifica!M:M, MATCH(G15, Classifica!C:C, 0)), 9, 1), "") -> W | U15: =IFERROR(IF(P15="","",COUNTIF(P15:T15,"W")*20+COUNTIF(P15:T15,"D")*7),"") -> 27 | V15: =IFERROR(ABS(U15-U16),"") -> 7 | W15: =COUNTIFS(Partite!$V:$V,1,Partite!$H:$H,Palinsesto!G15)+COUNTIFS(Partite!$V:$V,1,Partite!$J:$J,Palinsesto!G15) -> 6 | X15: =IFERROR(AVERAGE(IFERROR(INT(W15/(SUM(H15:J15))*100),""),IFERROR(INT(W16/(SUM(H16:J16))*100),"")),"") -> 48 | Y15: =INDEX(AC$4:AE$4, MATCH(MAX(AC15:AE15), AC15:AE15, 0)) -> 0-2 | Z15: =IFERROR(INT((LARGE(AC15:AE15,1)/SUM(H15:J15))*100),"") -> 73 | AA15: =COUNTIFS(Partite!$W:$W,1,Partite!$H:$H,Palinsesto!G15)+COUNTIFS(Partite!$W:$W,1,Partite!$J:$J,Palinsesto!G15) -> 13 | AB15: =IFERROR(INT(AVERAGE(AA15/(SUM(H15:J15))*100,(AA16/(SUM(H16:J16))*100))),"") -> 83 | AC15: =COUNTIFS(Partite!$X:$X,1,Partite!$H:$H,Palinsesto!G15)+COUNTIFS(Partite!$X:$X,1,Partite!$J:$J,Palinsesto!G15) -> 11 | AD15: =COUNTIFS(Partite!$Y:$Y,1,Partite!$H:$H,Palinsesto!G15)+COUNTIFS(Partite!$Y:$Y,1,Partite!$J:$J,Palinsesto!G15) -> 11 | AE15: =COUNTIFS(Partite!$Z:$Z,1,Partite!$H:$H,Palinsesto!G15)+COUNTIFS(Partite!$Z:$Z,1,Partite!$J:$J,Palinsesto!G15) -> 10
G16: =VLOOKUP($B$2+B15,Partite!$A$1:$AE$3000,10,FALSE) -> SJK | H16: =IFERROR(VLOOKUP(G16,Classifica!$C$2:$R$131,3,FALSE),"") -> 3 | I16: =IFERROR(VLOOKUP(G16,Classifica!$C$2:$R$131,4,FALSE),"") -> 5 | J16: =IFERROR(VLOOKUP(G16,Classifica!$C$2:$R$131,5,FALSE),"") -> 8 | K16: =IFERROR(VLOOKUP(G16,Classifica!$C$2:$R$131,6,FALSE),"") -> 18 | L16: =IFERROR(VLOOKUP(G16,Classifica!$C$2:$R$131,7,FALSE),"") -> 25 | M16: =IFERROR(VLOOKUP(G16,Classifica!$C$2:$R$131,8,FALSE),"") -> -7 | N16: =IFERROR(VLOOKUP(G16,Classifica!$C$2:$R$131,9,FALSE),"") -> 14 | O16: =IFERROR(VLOOKUP(G16,Classifica!$C$2:$R$131,16,FALSE),"") -> 10 | P16: =IFERROR(MID(INDEX(Classifica!M:M, MATCH(G16, Classifica!C:C, 0)), 1, 1), "") -> D | Q16: =IFERROR(MID(INDEX(Classifica!M:M, MATCH(G16, Classifica!C:C, 0)), 3, 1), "") -> D | R16: =IFERROR(MID(INDEX(Classifica!M:M, MATCH(G16, Classifica!C:C, 0)), 5, 1), "") -> W | S16: =IFERROR(MID(INDEX(Classifica!M:M, MATCH(G16, Classifica!C:C, 0)), 7, 1), "") -> L | T16: =IFERROR(MID(INDEX(Classifica!M:M, MATCH(G16, Classifica!C:C, 0)), 9, 1), "") -> L | U16: =IFERROR(IF(P16="","",COUNTIF(P16:T16,"W")*20+COUNTIF(P16:T16,"D")*7),"") -> 34 | W16: =COUNTIFS(Partite!$V:$V,1,Partite!$H:$H,Palinsesto!G16)+COUNTIFS(Partite!$V:$V,1,Partite!$J:$J,Palinsesto!G16) -> 9 | Y16: =INDEX(AC$4:AE$4, MATCH(MAX(AC16:AE16), AC16:AE16, 0)) -> 1-3 | Z16: =IFERROR(INT((LARGE(AC16:AE16,1)/SUM(H16:J16))*100),"") -> 81 | AA16: =COUNTIFS(Partite!$W:$W,1,Partite!$H:$H,Palinsesto!G16)+COUNTIFS(Partite!$W:$W,1,Partite!$J:$J,Palinsesto!G16) -> 13 | AC16: =COUNTIFS(Partite!$X:$X,1,Partite!$H:$H,Palinsesto!G16)+COUNTIFS(Partite!$X:$X,1,Partite!$J:$J,Palinsesto!G16) -> 12 | AD16: =COUNTIFS(Partite!$Y:$Y,1,Partite!$H:$H,Palinsesto!G16)+COUNTIFS(Partite!$Y:$Y,1,Partite!$J:$J,Palinsesto!G16) -> 13 | AE16: =COUNTIFS(Partite!$Z:$Z,1,Partite!$H:$H,Palinsesto!G16)+COUNTIFS(Partite!$Z:$Z,1,Partite!$J:$J,Palinsesto!G16) -> 7
B18: =B15+1 -> 5 | C18: =VLOOKUP($B$2+B18,Partite!$A$1:$AE$3000,2,FALSE) -> Swiss | D18: =VLOOKUP($B$2+B18,Partite!$A$1:$AE$3000,4,FALSE) -> 1 | E18: =VLOOKUP($B$2+B18,Partite!$A$1:$AE$3000,6,FALSE) -> 46228 | F18: =VLOOKUP($B$2+B18,Partite!$A$1:$AE$3000,7,FALSE) -> 18:00 | G18: =VLOOKUP($B$2+B18,Partite!$A$1:$AE$3000,8,FALSE) -> Lausanne-Sport | H18: =IFERROR(VLOOKUP(G18,Classifica!$C$2:$R$131,3,FALSE),"") | I18: =IFERROR(VLOOKUP(G18,Classifica!$C$2:$R$131,4,FALSE),"") | J18: =IFERROR(VLOOKUP(G18,Classifica!$C$2:$R$131,5,FALSE),"") | K18: =IFERROR(VLOOKUP(G18,Classifica!$C$2:$R$131,6,FALSE),"") | L18: =IFERROR(VLOOKUP(G18,Classifica!$C$2:$R$131,7,FALSE),"") | M18: =IFERROR(VLOOKUP(G18,Classifica!$C$2:$R$131,8,FALSE),"") | N18: =IFERROR(VLOOKUP(G18,Classifica!$C$2:$R$131,9,FALSE),"") | O18: =IFERROR(VLOOKUP(G18,Classifica!$C$2:$R$131,16,FALSE),"") | P18: =IFERROR(MID(INDEX(Classifica!M:M, MATCH(G18, Classifica!C:C, 0)), 1, 1), "") | Q18: =IFERROR(MID(INDEX(Classifica!M:M, MATCH(G18, Classifica!C:C, 0)), 3, 1), "") | R18: =IFERROR(MID(INDEX(Classifica!M:M, MATCH(G18, Classifica!C:C, 0)), 5, 1), "") | S18: =IFERROR(MID(INDEX(Classifica!M:M, MATCH(G18, Classifica!C:C, 0)), 7, 1), "") | T18: =IFERROR(MID(INDEX(Classifica!M:M, MATCH(G18, Classifica!C:C, 0)), 9, 1), "") | U18: =IFERROR(IF(P18="","",COUNTIF(P18:T18,"W")*20+COUNTIF(P18:T18,"D")*7),"") | V18: =IFERROR(ABS(U18-U19),"") | W18: =COUNTIFS(Partite!$V:$V,1,Partite!$H:$H,Palinsesto!G18)+COUNTIFS(Partite!$V:$V,1,Partite!$J:$J,Palinsesto!G18) -> 0 | X18: =IFERROR(AVERAGE(IFERROR(INT(W18/(SUM(H18:J18))*100),""),IFERROR(INT(W19/(SUM(H19:J19))*100),"")),"") | Y18: =INDEX(AC$4:AE$4, MATCH(MAX(AC18:AE18), AC18:AE18, 0)) -> 0-2 | Z18: =IFERROR(INT((LARGE(AC18:AE18,1)/SUM(H18:J18))*100),"") | AA18: =COUNTIFS(Partite!$W:$W,1,Partite!$H:$H,Palinsesto!G18)+COUNTIFS(Partite!$W:$W,1,Partite!$J:$J,Palinsesto!G18) -> 0 | AB18: =IFERROR(INT(AVERAGE(AA18/(SUM(H18:J18))*100,(AA19/(SUM(H19:J19))*100))),"") | AC18: =COUNTIFS(Partite!$X:$X,1,Partite!$H:$H,Palinsesto!G18)+COUNTIFS(Partite!$X:$X,1,Partite!$J:$J,Palinsesto!G18) -> 0 | AD18: =COUNTIFS(Partite!$Y:$Y,1,Partite!$H:$H,Palinsesto!G18)+COUNTIFS(Partite!$Y:$Y,1,Partite!$J:$J,Palinsesto!G18) -> 0 | AE18: =COUNTIFS(Partite!$Z:$Z,1,Partite!$H:$H,Palinsesto!G18)+COUNTIFS(Partite!$Z:$Z,1,Partite!$J:$J,Palinsesto!G18) -> 0
G19: =VLOOKUP($B$2+B18,Partite!$A$1:$AE$3000,10,FALSE) -> Grasshopper | H19: =IFERROR(VLOOKUP(G19,Classifica!$C$2:$R$131,3,FALSE),"") | I19: =IFERROR(VLOOKUP(G19,Classifica!$C$2:$R$131,4,FALSE),"") | J19: =IFERROR(VLOOKUP(G19,Classifica!$C$2:$R$131,5,FALSE),"") | K19: =IFERROR(VLOOKUP(G19,Classifica!$C$2:$R$131,6,FALSE),"") | L19: =IFERROR(VLOOKUP(G19,Classifica!$C$2:$R$131,7,FALSE),"") | M19: =IFERROR(VLOOKUP(G19,Classifica!$C$2:$R$131,8,FALSE),"") | N19: =IFERROR(VLOOKUP(G19,Classifica!$C$2:$R$131,9,FALSE),"") | O19: =IFERROR(VLOOKUP(G19,Classifica!$C$2:$R$131,16,FALSE),"") | P19: =IFERROR(MID(INDEX(Classifica!M:M, MATCH(G19, Classifica!C:C, 0)), 1, 1), "") | Q19: =IFERROR(MID(INDEX(Classifica!M:M, MATCH(G19, Classifica!C:C, 0)), 3, 1), "") | R19: =IFERROR(MID(INDEX(Classifica!M:M, MATCH(G19, Classifica!C:C, 0)), 5, 1), "") | S19: =IFERROR(MID(INDEX(Classifica!M:M, MATCH(G19, Classifica!C:C, 0)), 7, 1), "") | T19: =IFERROR(MID(INDEX(Classifica!M:M, MATCH(G19, Classifica!C:C, 0)), 9, 1), "") | U19: =IFERROR(IF(P19="","",COUNTIF(P19:T19,"W")*20+COUNTIF(P19:T19,"D")*7),"") | W19: =COUNTIFS(Partite!$V:$V,1,Partite!$H:$H,Palinsesto!G19)+COUNTIFS(Partite!$V:$V,1,Partite!$J:$J,Palinsesto!G19) -> 0 | Y19: =INDEX(AC$4:AE$4, MATCH(MAX(AC19:AE19), AC19:AE19, 0)) -> 0-2 | Z19: =IFERROR(INT((LARGE(AC19:AE19,1)/SUM(H19:J19))*100),"") | AA19: =COUNTIFS(Partite!$W:$W,1,Partite!$H:$H,Palinsesto!G19)+COUNTIFS(Partite!$W:$W,1,Partite!$J:$J,Palinsesto!G19) -> 0 | AC19: =COUNTIFS(Partite!$X:$X,1,Partite!$H:$H,Palinsesto!G19)+COUNTIFS(Partite!$X:$X,1,Partite!$J:$J,Palinsesto!G19) -> 0 | AD19: =COUNTIFS(Partite!$Y:$Y,1,Partite!$H:$H,Palinsesto!G19)+COUNTIFS(Partite!$Y:$Y,1,Partite!$J:$J,Palinsesto!G19) -> 0 | AE19: =COUNTIFS(Partite!$Z:$Z,1,Partite!$H:$H,Palinsesto!G19)+COUNTIFS(Partite!$Z:$Z,1,Partite!$J:$J,Palinsesto!G19) -> 0
B21: =B18+1 -> 6 | C21: =VLOOKUP($B$2+B21,Partite!$A$1:$AE$3000,2,FALSE) -> Swiss | D21: =VLOOKUP($B$2+B21,Partite!$A$1:$AE$3000,4,FALSE) -> 1 | E21: =VLOOKUP($B$2+B21,Partite!$A$1:$AE$3000,6,FALSE) -> 46228 | F21: =VLOOKUP($B$2+B21,Partite!$A$1:$AE$3000,7,FALSE) -> 18:00 | G21: =VLOOKUP($B$2+B21,Partite!$A$1:$AE$3000,8,FALSE) -> Servette FC | H21: =IFERROR(VLOOKUP(G21,Classifica!$C$2:$R$131,3,FALSE),"") | I21: =IFERROR(VLOOKUP(G21,Classifica!$C$2:$R$131,4,FALSE),"") | J21: =IFERROR(VLOOKUP(G21,Classifica!$C$2:$R$131,5,FALSE),"") | K21: =IFERROR(VLOOKUP(G21,Classifica!$C$2:$R$131,6,FALSE),"") | L21: =IFERROR(VLOOKUP(G21,Classifica!$C$2:$R$131,7,FALSE),"") | M21: =IFERROR(VLOOKUP(G21,Classifica!$C$2:$R$131,8,FALSE),"") | N21: =IFERROR(VLOOKUP(G21,Classifica!$C$2:$R$131,9,FALSE),"") | O21: =IFERROR(VLOOKUP(G21,Classifica!$C$2:$R$131,16,FALSE),"") | P21: =IFERROR(MID(INDEX(Classifica!M:M, MATCH(G21, Classifica!C:C, 0)), 1, 1), "") | Q21: =IFERROR(MID(INDEX(Classifica!M:M, MATCH(G21, Classifica!C:C, 0)), 3, 1), "") | R21: =IFERROR(MID(INDEX(Classifica!M:M, MATCH(G21, Classifica!C:C, 0)), 5, 1), "") | S21: =IFERROR(MID(INDEX(Classifica!M:M, MATCH(G21, Classifica!C:C, 0)), 7, 1), "") | T21: =IFERROR(MID(INDEX(Classifica!M:M, MATCH(G21, Classifica!C:C, 0)), 9, 1), "") | U21: =IFERROR(IF(P21="","",COUNTIF(P21:T21,"W")*20+COUNTIF(P21:T21,"D")*7),"") | V21: =IFERROR(ABS(U21-U22),"") | W21: =COUNTIFS(Partite!$V:$V,1,Partite!$H:$H,Palinsesto!G21)+COUNTIFS(Partite!$V:$V,1,Partite!$J:$J,Palinsesto!G21) -> 0 | X21: =IFERROR(AVERAGE(IFERROR(INT(W21/(SUM(H21:J21))*100),""),IFERROR(INT(W22/(SUM(H22:J22))*100),"")),"") | Y21: =INDEX(AC$4:AE$4, MATCH(MAX(AC21:AE21), AC21:AE21, 0)) -> 0-2 | Z21: =IFERROR(INT((LARGE(AC21:AE21,1)/SUM(H21:J21))*100),"") | AA21: =COUNTIFS(Partite!$W:$W,1,Partite!$H:$H,Palinsesto!G21)+COUNTIFS(Partite!$W:$W,1,Partite!$J:$J,Palinsesto!G21) -> 0 | AB21: =IFERROR(INT(AVERAGE(AA21/(SUM(H21:J21))*100,(AA22/(SUM(H22:J22))*100))),"") | AC21: =COUNTIFS(Partite!$X:$X,1,Partite!$H:$H,Palinsesto!G21)+COUNTIFS(Partite!$X:$X,1,Partite!$J:$J,Palinsesto!G21) -> 0 | AD21: =COUNTIFS(Partite!$Y:$Y,1,Partite!$H:$H,Palinsesto!G21)+COUNTIFS(Partite!$Y:$Y,1,Partite!$J:$J,Palinsesto!G21) -> 0 | AE21: =COUNTIFS(Partite!$Z:$Z,1,Partite!$H:$H,Palinsesto!G21)+COUNTIFS(Partite!$Z:$Z,1,Partite!$J:$J,Palinsesto!G21) -> 0
G22: =VLOOKUP($B$2+B21,Partite!$A$1:$AE$3000,10,FALSE) -> Basel | H22: =IFERROR(VLOOKUP(G22,Classifica!$C$2:$R$131,3,FALSE),"") | I22: =IFERROR(VLOOKUP(G22,Classifica!$C$2:$R$131,4,FALSE),"") | J22: =IFERROR(VLOOKUP(G22,Classifica!$C$2:$R$131,5,FALSE),"") | K22: =IFERROR(VLOOKUP(G22,Classifica!$C$2:$R$131,6,FALSE),"") | L22: =IFERROR(VLOOKUP(G22,Classifica!$C$2:$R$131,7,FALSE),"") | M22: =IFERROR(VLOOKUP(G22,Classifica!$C$2:$R$131,8,FALSE),"") | N22: =IFERROR(VLOOKUP(G22,Classifica!$C$2:$R$131,9,FALSE),"") | O22: =IFERROR(VLOOKUP(G22,Classifica!$C$2:$R$131,16,FALSE),"") | P22: =IFERROR(MID(INDEX(Classifica!M:M, MATCH(G22, Classifica!C:C, 0)), 1, 1), "") | Q22: =IFERROR(MID(INDEX(Classifica!M:M, MATCH(G22, Classifica!C:C, 0)), 3, 1), "") | R22: =IFERROR(MID(INDEX(Classifica!M:M, MATCH(G22, Classifica!C:C, 0)), 5, 1), "") | S22: =IFERROR(MID(INDEX(Classifica!M:M, MATCH(G22, Classifica!C:C, 0)), 7, 1), "") | T22: =IFERROR(MID(INDEX(Classifica!M:M, MATCH(G22, Classifica!C:C, 0)), 9, 1), "") | U22: =IFERROR(IF(P22="","",COUNTIF(P22:T22,"W")*20+COUNTIF(P22:T22,"D")*7),"") | W22: =COUNTIFS(Partite!$V:$V,1,Partite!$H:$H,Palinsesto!G22)+COUNTIFS(Partite!$V:$V,1,Partite!$J:$J,Palinsesto!G22) -> 0 | Y22: =INDEX(AC$4:AE$4, MATCH(MAX(AC22:AE22), AC22:AE22, 0)) -> 0-2 | Z22: =IFERROR(INT((LARGE(AC22:AE22,1)/SUM(H22:J22))*100),"") | AA22: =COUNTIFS(Partite!$W:$W,1,Partite!$H:$H,Palinsesto!G22)+COUNTIFS(Partite!$W:$W,1,Partite!$J:$J,Palinsesto!G22) -> 0 | AC22: =COUNTIFS(Partite!$X:$X,1,Partite!$H:$H,Palinsesto!G22)+COUNTIFS(Partite!$X:$X,1,Partite!$J:$J,Palinsesto!G22) -> 0 | AD22: =COUNTIFS(Partite!$Y:$Y,1,Partite!$H:$H,Palinsesto!G22)+COUNTIFS(Partite!$Y:$Y,1,Partite!$J:$J,Palinsesto!G22) -> 0 | AE22: =COUNTIFS(Partite!$Z:$Z,1,Partite!$H:$H,Palinsesto!G22)+COUNTIFS(Partite!$Z:$Z,1,Partite!$J:$J,Palinsesto!G22) -> 0
B24: =B21+1 -> 7 | C24: =VLOOKUP($B$2+B24,Partite!$A$1:$AE$3000,2,FALSE) -> Swiss | D24: =VLOOKUP($B$2+B24,Partite!$A$1:$AE$3000,4,FALSE) -> 1 | E24: =VLOOKUP($B$2+B24,Partite!$A$1:$AE$3000,6,FALSE) -> 46228 | F24: =VLOOKUP($B$2+B24,Partite!$A$1:$AE$3000,7,FALSE) -> 20:30 | G24: =VLOOKUP($B$2+B24,Partite!$A$1:$AE$3000,8,FALSE) -> Luzern | H24: =IFERROR(VLOOKUP(G24,Classifica!$C$2:$R$131,3,FALSE),"") | I24: =IFERROR(VLOOKUP(G24,Classifica!$C$2:$R$131,4,FALSE),"") | J24: =IFERROR(VLOOKUP(G24,Classifica!$C$2:$R$131,5,FALSE),"") | K24: =IFERROR(VLOOKUP(G24,Classifica!$C$2:$R$131,6,FALSE),"") | L24: =IFERROR(VLOOKUP(G24,Classifica!$C$2:$R$131,7,FALSE),"") | M24: =IFERROR(VLOOKUP(G24,Classifica!$C$2:$R$131,8,FALSE),"") | N24: =IFERROR(VLOOKUP(G24,Classifica!$C$2:$R$131,9,FALSE),"") | O24: =IFERROR(VLOOKUP(G24,Classifica!$C$2:$R$131,16,FALSE),"") | P24: =IFERROR(MID(INDEX(Classifica!M:M, MATCH(G24, Classifica!C:C, 0)), 1, 1), "") | Q24: =IFERROR(MID(INDEX(Classifica!M:M, MATCH(G24, Classifica!C:C, 0)), 3, 1), "") | R24: =IFERROR(MID(INDEX(Classifica!M:M, MATCH(G24, Classifica!C:C, 0)), 5, 1), "") | S24: =IFERROR(MID(INDEX(Classifica!M:M, MATCH(G24, Classifica!C:C, 0)), 7, 1), "") | T24: =IFERROR(MID(INDEX(Classifica!M:M, MATCH(G24, Classifica!C:C, 0)), 9, 1), "") | U24: =IFERROR(IF(P24="","",COUNTIF(P24:T24,"W")*20+COUNTIF(P24:T24,"D")*7),"") | V24: =IFERROR(ABS(U24-U25),"") | W24: =COUNTIFS(Partite!$V:$V,1,Partite!$H:$H,Palinsesto!G24)+COUNTIFS(Partite!$V:$V,1,Partite!$J:$J,Palinsesto!G24) -> 0 | X24: =IFERROR(AVERAGE(IFERROR(INT(W24/(SUM(H24:J24))*100),""),IFERROR(INT(W25/(SUM(H25:J25))*100),"")),"") | Y24: =INDEX(AC$4:AE$4, MATCH(MAX(AC24:AE24), AC24:AE24, 0)) -> 0-2 | Z24: =IFERROR(INT((LARGE(AC24:AE24,1)/SUM(H24:J24))*100),"") | AA24: =COUNTIFS(Partite!$W:$W,1,Partite!$H:$H,Palinsesto!G24)+COUNTIFS(Partite!$W:$W,1,Partite!$J:$J,Palinsesto!G24) -> 0 | AB24: =IFERROR(INT(AVERAGE(AA24/(SUM(H24:J24))*100,(AA25/(SUM(H25:J25))*100))),"") | AC24: =COUNTIFS(Partite!$X:$X,1,Partite!$H:$H,Palinsesto!G24)+COUNTIFS(Partite!$X:$X,1,Partite!$J:$J,Palinsesto!G24) -> 0 | AD24: =COUNTIFS(Partite!$Y:$Y,1,Partite!$H:$H,Palinsesto!G24)+COUNTIFS(Partite!$Y:$Y,1,Partite!$J:$J,Palinsesto!G24) -> 0 | AE24: =COUNTIFS(Partite!$Z:$Z,1,Partite!$H:$H,Palinsesto!G24)+COUNTIFS(Partite!$Z:$Z,1,Partite!$J:$J,Palinsesto!G24) -> 0
G25: =VLOOKUP($B$2+B24,Partite!$A$1:$AE$3000,10,FALSE) -> Thun | H25: =IFERROR(VLOOKUP(G25,Classifica!$C$2:$R$131,3,FALSE),"") | I25: =IFERROR(VLOOKUP(G25,Classifica!$C$2:$R$131,4,FALSE),"") | J25: =IFERROR(VLOOKUP(G25,Classifica!$C$2:$R$131,5,FALSE),"") | K25: =IFERROR(VLOOKUP(G25,Classifica!$C$2:$R$131,6,FALSE),"") | L25: =IFERROR(VLOOKUP(G25,Classifica!$C$2:$R$131,7,FALSE),"") | M25: =IFERROR(VLOOKUP(G25,Classifica!$C$2:$R$131,8,FALSE),"") | N25: =IFERROR(VLOOKUP(G25,Classifica!$C$2:$R$131,9,FALSE),"") | O25: =IFERROR(VLOOKUP(G25,Classifica!$C$2:$R$131,16,FALSE),"") | P25: =IFERROR(MID(INDEX(Classifica!M:M, MATCH(G25, Classifica!C:C, 0)), 1, 1), "") | Q25: =IFERROR(MID(INDEX(Classifica!M:M, MATCH(G25, Classifica!C:C, 0)), 3, 1), "") | R25: =IFERROR(MID(INDEX(Classifica!M:M, MATCH(G25, Classifica!C:C, 0)), 5, 1), "") | S25: =IFERROR(MID(INDEX(Classifica!M:M, MATCH(G25, Classifica!C:C, 0)), 7, 1), "") | T25: =IFERROR(MID(INDEX(Classifica!M:M, MATCH(G25, Classifica!C:C, 0)), 9, 1), "") | U25: =IFERROR(IF(P25="","",COUNTIF(P25:T25,"W")*20+COUNTIF(P25:T25,"D")*7),"") | W25: =COUNTIFS(Partite!$V:$V,1,Partite!$H:$H,Palinsesto!G25)+COUNTIFS(Partite!$V:$V,1,Partite!$J:$J,Palinsesto!G25) -> 0 | Y25: =INDEX(AC$4:AE$4, MATCH(MAX(AC25:AE25), AC25:AE25, 0)) -> 0-2 | Z25: =IFERROR(INT((LARGE(AC25:AE25,1)/SUM(H25:J25))*100),"") | AA25: =COUNTIFS(Partite!$W:$W,1,Partite!$H:$H,Palinsesto!G25)+COUNTIFS(Partite!$W:$W,1,Partite!$J:$J,Palinsesto!G25) -> 0 | AC25: =COUNTIFS(Partite!$X:$X,1,Partite!$H:$H,Palinsesto!G25)+COUNTIFS(Partite!$X:$X,1,Partite!$J:$J,Palinsesto!G25) -> 0 | AD25: =COUNTIFS(Partite!$Y:$Y,1,Partite!$H:$H,Palinsesto!G25)+COUNTIFS(Partite!$Y:$Y,1,Partite!$J:$J,Palinsesto!G25) -> 0 | AE25: =COUNTIFS(Partite!$Z:$Z,1,Partite!$H:$H,Palinsesto!G25)+COUNTIFS(Partite!$Z:$Z,1,Partite!$J:$J,Palinsesto!G25) -> 0
B27: =B24+1 -> 8 | C27: =VLOOKUP($B$2+B27,Partite!$A$1:$AE$3000,2,FALSE) -> Veikkausliiga | D27: =VLOOKUP($B$2+B27,Partite!$A$1:$AE$3000,4,FALSE) -> 17 | E27: =VLOOKUP($B$2+B27,Partite!$A$1:$AE$3000,6,FALSE) -> 46228 | F27: =VLOOKUP($B$2+B27,Partite!$A$1:$AE$3000,7,FALSE) -> 16:30 (15:30) | G27: =VLOOKUP($B$2+B27,Partite!$A$1:$AE$3000,8,FALSE) -> IFK Mariehamn | H27: =IFERROR(VLOOKUP(G27,Classifica!$C$2:$R$131,3,FALSE),"") -> 0 | I27: =IFERROR(VLOOKUP(G27,Classifica!$C$2:$R$131,4,FALSE),"") -> 4 | J27: =IFERROR(VLOOKUP(G27,Classifica!$C$2:$R$131,5,FALSE),"") -> 11 | K27: =IFERROR(VLOOKUP(G27,Classifica!$C$2:$R$131,6,FALSE),"") -> 8 | L27: =IFERROR(VLOOKUP(G27,Classifica!$C$2:$R$131,7,FALSE),"") -> 33 | M27: =IFERROR(VLOOKUP(G27,Classifica!$C$2:$R$131,8,FALSE),"") -> -25 | N27: =IFERROR(VLOOKUP(G27,Classifica!$C$2:$R$131,9,FALSE),"") -> 4 | O27: =IFERROR(VLOOKUP(G27,Classifica!$C$2:$R$131,16,FALSE),"") -> 12 | P27: =IFERROR(MID(INDEX(Classifica!M:M, MATCH(G27, Classifica!C:C, 0)), 1, 1), "") -> L | Q27: =IFERROR(MID(INDEX(Classifica!M:M, MATCH(G27, Classifica!C:C, 0)), 3, 1), "") -> L | R27: =IFERROR(MID(INDEX(Classifica!M:M, MATCH(G27, Classifica!C:C, 0)), 5, 1), "") -> L | S27: =IFERROR(MID(INDEX(Classifica!M:M, MATCH(G27, Classifica!C:C, 0)), 7, 1), "") -> L | T27: =IFERROR(MID(INDEX(Classifica!M:M, MATCH(G27, Classifica!C:C, 0)), 9, 1), "") -> L | U27: =IFERROR(IF(P27="","",COUNTIF(P27:T27,"W")*20+COUNTIF(P27:T27,"D")*7),"") -> 0 | V27: =IFERROR(ABS(U27-U28),"") -> 27 | W27: =COUNTIFS(Partite!$V:$V,1,Partite!$H:$H,Palinsesto!G27)+COUNTIFS(Partite!$V:$V,1,Partite!$J:$J,Palinsesto!G27) -> 11 | X27: =IFERROR(AVERAGE(IFERROR(INT(W27/(SUM(H27:J27))*100),""),IFERROR(INT(W28/(SUM(H28:J28))*100),"")),"") -> 70.5 | Y27: =INDEX(AC$4:AE$4, MATCH(MAX(AC27:AE27), AC27:AE27, 0)) -> 0-2 | Z27: =IFERROR(INT((LARGE(AC27:AE27,1)/SUM(H27:J27))*100),"") -> 80 | AA27: =COUNTIFS(Partite!$W:$W,1,Partite!$H:$H,Palinsesto!G27)+COUNTIFS(Partite!$W:$W,1,Partite!$J:$J,Palinsesto!G27) -> 13 | AB27: =IFERROR(INT(AVERAGE(AA27/(SUM(H27:J27))*100,(AA28/(SUM(H28:J28))*100))),"") -> 74 | AC27: =COUNTIFS(Partite!$X:$X,1,Partite!$H:$H,Palinsesto!G27)+COUNTIFS(Partite!$X:$X,1,Partite!$J:$J,Palinsesto!G27) -> 12 | AD27: =COUNTIFS(Partite!$Y:$Y,1,Partite!$H:$H,Palinsesto!G27)+COUNTIFS(Partite!$Y:$Y,1,Partite!$J:$J,Palinsesto!G27) -> 9 | AE27: =COUNTIFS(Partite!$Z:$Z,1,Partite!$H:$H,Palinsesto!G27)+COUNTIFS(Partite!$Z:$Z,1,Partite!$J:$J,Palinsesto!G27) -> 6
G28: =VLOOKUP($B$2+B27,Partite!$A$1:$AE$3000,10,FALSE) -> AC Oulu | H28: =IFERROR(VLOOKUP(G28,Classifica!$C$2:$R$131,3,FALSE),"") -> 8 | I28: =IFERROR(VLOOKUP(G28,Classifica!$C$2:$R$131,4,FALSE),"") -> 2 | J28: =IFERROR(VLOOKUP(G28,Classifica!$C$2:$R$131,5,FALSE),"") -> 6 | K28: =IFERROR(VLOOKUP(G28,Classifica!$C$2:$R$131,6,FALSE),"") -> 20 | L28: =IFERROR(VLOOKUP(G28,Classifica!$C$2:$R$131,7,FALSE),"") -> 20 | M28: =IFERROR(VLOOKUP(G28,Classifica!$C$2:$R$131,8,FALSE),"") -> 0 | N28: =IFERROR(VLOOKUP(G28,Classifica!$C$2:$R$131,9,FALSE),"") -> 26 | O28: =IFERROR(VLOOKUP(G28,Classifica!$C$2:$R$131,16,FALSE),"") -> 4 | P28: =IFERROR(MID(INDEX(Classifica!M:M, MATCH(G28, Classifica!C:C, 0)), 1, 1), "") -> W | Q28: =IFERROR(MID(INDEX(Classifica!M:M, MATCH(G28, Classifica!C:C, 0)), 3, 1), "") -> L | R28: =IFERROR(MID(INDEX(Classifica!M:M, MATCH(G28, Classifica!C:C, 0)), 5, 1), "") -> D | S28: =IFERROR(MID(INDEX(Classifica!M:M, MATCH(G28, Classifica!C:C, 0)), 7, 1), "") -> L | T28: =IFERROR(MID(INDEX(Classifica!M:M, MATCH(G28, Classifica!C:C, 0)), 9, 1), "") -> L | U28: =IFERROR(IF(P28="","",COUNTIF(P28:T28,"W")*20+COUNTIF(P28:T28,"D")*7),"") -> 27 | W28: =COUNTIFS(Partite!$V:$V,1,Partite!$H:$H,Palinsesto!G28)+COUNTIFS(Partite!$V:$V,1,Partite!$J:$J,Palinsesto!G28) -> 11 | Y28: =INDEX(AC$4:AE$4, MATCH(MAX(AC28:AE28), AC28:AE28, 0)) -> 0-2 | Z28: =IFERROR(INT((LARGE(AC28:AE28,1)/SUM(H28:J28))*100),"") -> 81 | AA28: =COUNTIFS(Partite!$W:$W,1,Partite!$H:$H,Palinsesto!G28)+COUNTIFS(Partite!$W:$W,1,Partite!$J:$J,Palinsesto!G28) -> 10 | AC28: =COUNTIFS(Partite!$X:$X,1,Partite!$H:$H,Palinsesto!G28)+COUNTIFS(Partite!$X:$X,1,Partite!$J:$J,Palinsesto!G28) -> 13 | AD28: =COUNTIFS(Partite!$Y:$Y,1,Partite!$H:$H,Palinsesto!G28)+COUNTIFS(Partite!$Y:$Y,1,Partite!$J:$J,Palinsesto!G28) -> 11 | AE28: =COUNTIFS(Partite!$Z:$Z,1,Partite!$H:$H,Palinsesto!G28)+COUNTIFS(Partite!$Z:$Z,1,Partite!$J:$J,Palinsesto!G28) -> 7
B30: =B27+1 -> 9 | C30: =VLOOKUP($B$2+B30,Partite!$A$1:$AE$3000,2,FALSE) -> Veikkausliiga | D30: =VLOOKUP($B$2+B30,Partite!$A$1:$AE$3000,4,FALSE) -> 17 | E30: =VLOOKUP($B$2+B30,Partite!$A$1:$AE$3000,6,FALSE) -> 46228 | F30: =VLOOKUP($B$2+B30,Partite!$A$1:$AE$3000,7,FALSE) -> 17:00 (16:00) | G30: =VLOOKUP($B$2+B30,Partite!$A$1:$AE$3000,8,FALSE) -> KuPS | H30: =IFERROR(VLOOKUP(G30,Classifica!$C$2:$R$131,3,FALSE),"") -> 9 | I30: =IFERROR(VLOOKUP(G30,Classifica!$C$2:$R$131,4,FALSE),"") -> 6 | J30: =IFERROR(VLOOKUP(G30,Classifica!$C$2:$R$131,5,FALSE),"") -> 1 | K30: =IFERROR(VLOOKUP(G30,Classifica!$C$2:$R$131,6,FALSE),"") -> 29 | L30: =IFERROR(VLOOKUP(G30,Classifica!$C$2:$R$131,7,FALSE),"") -> 15 | M30: =IFERROR(VLOOKUP(G30,Classifica!$C$2:$R$131,8,FALSE),"") -> 14 | N30: =IFERROR(VLOOKUP(G30,Classifica!$C$2:$R$131,9,FALSE),"") -> 33 | O30: =IFERROR(VLOOKUP(G30,Classifica!$C$2:$R$131,16,FALSE),"") -> 1 | P30: =IFERROR(MID(INDEX(Classifica!M:M, MATCH(G30, Classifica!C:C, 0)), 1, 1), "") -> D | Q30: =IFERROR(MID(INDEX(Classifica!M:M, MATCH(G30, Classifica!C:C, 0)), 3, 1), "") -> W | R30: =IFERROR(MID(INDEX(Classifica!M:M, MATCH(G30, Classifica!C:C, 0)), 5, 1), "") -> W | S30: =IFERROR(MID(INDEX(Classifica!M:M, MATCH(G30, Classifica!C:C, 0)), 7, 1), "") -> W | T30: =IFERROR(MID(INDEX(Classifica!M:M, MATCH(G30, Classifica!C:C, 0)), 9, 1), "") -> W | U30: =IFERROR(IF(P30="","",COUNTIF(P30:T30,"W")*20+COUNTIF(P30:T30,"D")*7),"") -> 87 | V30: =IFERROR(ABS(U30-U31),"") -> 20 | W30: =COUNTIFS(Partite!$V:$V,1,Partite!$H:$H,Palinsesto!G30)+COUNTIFS(Partite!$V:$V,1,Partite!$J:$J,Palinsesto!G30) -> 8 | X30: =IFERROR(AVERAGE(IFERROR(INT(W30/(SUM(H30:J30))*100),""),IFERROR(INT(W31/(SUM(H31:J31))*100),"")),"") -> 50 | Y30: =INDEX(AC$4:AE$4, MATCH(MAX(AC30:AE30), AC30:AE30, 0)) -> 0-2 | Z30: =IFERROR(INT((LARGE(AC30:AE30,1)/SUM(H30:J30))*100),"") -> 81 | AA30: =COUNTIFS(Partite!$W:$W,1,Partite!$H:$H,Palinsesto!G30)+COUNTIFS(Partite!$W:$W,1,Partite!$J:$J,Palinsesto!G30) -> 14 | AB30: =IFERROR(INT(AVERAGE(AA30/(SUM(H30:J30))*100,(AA31/(SUM(H31:J31))*100))),"") -> 75 | AC30: =COUNTIFS(Partite!$X:$X,1,Partite!$H:$H,Palinsesto!G30)+COUNTIFS(Partite!$X:$X,1,Partite!$J:$J,Palinsesto!G30) -> 13 | AD30: =COUNTIFS(Partite!$Y:$Y,1,Partite!$H:$H,Palinsesto!G30)+COUNTIFS(Partite!$Y:$Y,1,Partite!$J:$J,Palinsesto!G30) -> 12 | AE30: =COUNTIFS(Partite!$Z:$Z,1,Partite!$H:$H,Palinsesto!G30)+COUNTIFS(Partite!$Z:$Z,1,Partite!$J:$J,Palinsesto!G30) -> 5
G31: =VLOOKUP($B$2+B30,Partite!$A$1:$AE$3000,10,FALSE) -> VPS | H31: =IFERROR(VLOOKUP(G31,Classifica!$C$2:$R$131,3,FALSE),"") -> 7 | I31: =IFERROR(VLOOKUP(G31,Classifica!$C$2:$R$131,4,FALSE),"") -> 6 | J31: =IFERROR(VLOOKUP(G31,Classifica!$C$2:$R$131,5,FALSE),"") -> 3 | K31: =IFERROR(VLOOKUP(G31,Classifica!$C$2:$R$131,6,FALSE),"") -> 23 | L31: =IFERROR(VLOOKUP(G31,Classifica!$C$2:$R$131,7,FALSE),"") -> 13 | M31: =IFERROR(VLOOKUP(G31,Classifica!$C$2:$R$131,8,FALSE),"") -> 10 | N31: =IFERROR(VLOOKUP(G31,Classifica!$C$2:$R$131,9,FALSE),"") -> 27 | O31: =IFERROR(VLOOKUP(G31,Classifica!$C$2:$R$131,16,FALSE),"") -> 3 | P31: =IFERROR(MID(INDEX(Classifica!M:M, MATCH(G31, Classifica!C:C, 0)), 1, 1), "") -> W | Q31: =IFERROR(MID(INDEX(Classifica!M:M, MATCH(G31, Classifica!C:C, 0)), 3, 1), "") -> D | R31: =IFERROR(MID(INDEX(Classifica!M:M, MATCH(G31, Classifica!C:C, 0)), 5, 1), "") -> W | S31: =IFERROR(MID(INDEX(Classifica!M:M, MATCH(G31, Classifica!C:C, 0)), 7, 1), "") -> W | T31: =IFERROR(MID(INDEX(Classifica!M:M, MATCH(G31, Classifica!C:C, 0)), 9, 1), "") -> L | U31: =IFERROR(IF(P31="","",COUNTIF(P31:T31,"W")*20+COUNTIF(P31:T31,"D")*7),"") -> 67 | W31: =COUNTIFS(Partite!$V:$V,1,Partite!$H:$H,Palinsesto!G31)+COUNTIFS(Partite!$V:$V,1,Partite!$J:$J,Palinsesto!G31) -> 8 | Y31: =INDEX(AC$4:AE$4, MATCH(MAX(AC31:AE31), AC31:AE31, 0)) -> 0-2 | Z31: =IFERROR(INT((LARGE(AC31:AE31,1)/SUM(H31:J31))*100),"") -> 81 | AA31: =COUNTIFS(Partite!$W:$W,1,Partite!$H:$H,Palinsesto!G31)+COUNTIFS(Partite!$W:$W,1,Partite!$J:$J,Palinsesto!G31) -> 10 | AC31: =COUNTIFS(Partite!$X:$X,1,Partite!$H:$H,Palinsesto!G31)+COUNTIFS(Partite!$X:$X,1,Partite!$J:$J,Palinsesto!G31) -> 13 | AD31: =COUNTIFS(Partite!$Y:$Y,1,Partite!$H:$H,Palinsesto!G31)+COUNTIFS(Partite!$Y:$Y,1,Partite!$J:$J,Palinsesto!G31) -> 11 | AE31: =COUNTIFS(Partite!$Z:$Z,1,Partite!$H:$H,Palinsesto!G31)+COUNTIFS(Partite!$Z:$Z,1,Partite!$J:$J,Palinsesto!G31) -> 5
B33: =B30+1 -> 10 | C33: =VLOOKUP($B$2+B33,Partite!$A$1:$AE$3000,2,FALSE) -> Allsvenskan | D33: =VLOOKUP($B$2+B33,Partite!$A$1:$AE$3000,4,FALSE) -> 14 | E33: =VLOOKUP($B$2+B33,Partite!$A$1:$AE$3000,6,FALSE) -> 46228 | F33: =VLOOKUP($B$2+B33,Partite!$A$1:$AE$3000,7,FALSE) -> 15:00 | G33: =VLOOKUP($B$2+B33,Partite!$A$1:$AE$3000,8,FALSE) -> Degerfors | H33: =IFERROR(VLOOKUP(G33,Classifica!$C$2:$R$131,3,FALSE),"") -> 2 | I33: =IFERROR(VLOOKUP(G33,Classifica!$C$2:$R$131,4,FALSE),"") -> 4 | J33: =IFERROR(VLOOKUP(G33,Classifica!$C$2:$R$131,5,FALSE),"") -> 6 | K33: =IFERROR(VLOOKUP(G33,Classifica!$C$2:$R$131,6,FALSE),"") -> 12 | L33: =IFERROR(VLOOKUP(G33,Classifica!$C$2:$R$131,7,FALSE),"") -> 19 | M33: =IFERROR(VLOOKUP(G33,Classifica!$C$2:$R$131,8,FALSE),"") -> -7 | N33: =IFERROR(VLOOKUP(G33,Classifica!$C$2:$R$131,9,FALSE),"") -> 10 | O33: =IFERROR(VLOOKUP(G33,Classifica!$C$2:$R$131,16,FALSE),"") -> 14 | P33: =IFERROR(MID(INDEX(Classifica!M:M, MATCH(G33, Classifica!C:C, 0)), 1, 1), "") -> D | Q33: =IFERROR(MID(INDEX(Classifica!M:M, MATCH(G33, Classifica!C:C, 0)), 3, 1), "") -> L | R33: =IFERROR(MID(INDEX(Classifica!M:M, MATCH(G33, Classifica!C:C, 0)), 5, 1), "") -> D | S33: =IFERROR(MID(INDEX(Classifica!M:M, MATCH(G33, Classifica!C:C, 0)), 7, 1), "") -> L | T33: =IFERROR(MID(INDEX(Classifica!M:M, MATCH(G33, Classifica!C:C, 0)), 9, 1), "") -> L | U33: =IFERROR(IF(P33="","",COUNTIF(P33:T33,"W")*20+COUNTIF(P33:T33,"D")*7),"") -> 14 | V33: =IFERROR(ABS(U33-U34),"") -> 46 | W33: =COUNTIFS(Partite!$V:$V,1,Partite!$H:$H,Palinsesto!G33)+COUNTIFS(Partite!$V:$V,1,Partite!$J:$J,Palinsesto!G33) -> 8 | X33: =IFERROR(AVERAGE(IFERROR(INT(W33/(SUM(H33:J33))*100),""),IFERROR(INT(W34/(SUM(H34:J34))*100),"")),"") -> 55.5 | Y33: =INDEX(AC$4:AE$4, MATCH(MAX(AC33:AE33), AC33:AE33, 0)) -> 0-2 | Z33: =IFERROR(INT((LARGE(AC33:AE33,1)/SUM(H33:J33))*100),"") -> 100 | AA33: =COUNTIFS(Partite!$W:$W,1,Partite!$H:$H,Palinsesto!G33)+COUNTIFS(Partite!$W:$W,1,Partite!$J:$J,Palinsesto!G33) -> 11 | AB33: =IFERROR(INT(AVERAGE(AA33/(SUM(H33:J33))*100,(AA34/(SUM(H34:J34))*100))),"") -> 86 | AC33: =COUNTIFS(Partite!$X:$X,1,Partite!$H:$H,Palinsesto!G33)+COUNTIFS(Partite!$X:$X,1,Partite!$J:$J,Palinsesto!G33) -> 12 | AD33: =COUNTIFS(Partite!$Y:$Y,1,Partite!$H:$H,Palinsesto!G33)+COUNTIFS(Partite!$Y:$Y,1,Partite!$J:$J,Palinsesto!G33) -> 8 | AE33: =COUNTIFS(Partite!$Z:$Z,1,Partite!$H:$H,Palinsesto!G33)+COUNTIFS(Partite!$Z:$Z,1,Partite!$J:$J,Palinsesto!G33) -> 5
G34: =VLOOKUP($B$2+B33,Partite!$A$1:$AE$3000,10,FALSE) -> Djurgården | H34: =IFERROR(VLOOKUP(G34,Classifica!$C$2:$R$131,3,FALSE),"") -> 6 | I34: =IFERROR(VLOOKUP(G34,Classifica!$C$2:$R$131,4,FALSE),"") -> 1 | J34: =IFERROR(VLOOKUP(G34,Classifica!$C$2:$R$131,5,FALSE),"") -> 4 | K34: =IFERROR(VLOOKUP(G34,Classifica!$C$2:$R$131,6,FALSE),"") -> 26 | L34: =IFERROR(VLOOKUP(G34,Classifica!$C$2:$R$131,7,FALSE),"") -> 15 | M34: =IFERROR(VLOOKUP(G34,Classifica!$C$2:$R$131,8,FALSE),"") -> 11 | N34: =IFERROR(VLOOKUP(G34,Classifica!$C$2:$R$131,9,FALSE),"") -> 19 | O34: =IFERROR(VLOOKUP(G34,Classifica!$C$2:$R$131,16,FALSE),"") -> 5 | P34: =IFERROR(MID(INDEX(Classifica!M:M, MATCH(G34, Classifica!C:C, 0)), 1, 1), "") -> W | Q34: =IFERROR(MID(INDEX(Classifica!M:M, MATCH(G34, Classifica!C:C, 0)), 3, 1), "") -> L | R34: =IFERROR(MID(INDEX(Classifica!M:M, MATCH(G34, Classifica!C:C, 0)), 5, 1), "") -> L | S34: =IFERROR(MID(INDEX(Classifica!M:M, MATCH(G34, Classifica!C:C, 0)), 7, 1), "") -> W | T34: =IFERROR(MID(INDEX(Classifica!M:M, MATCH(G34, Classifica!C:C, 0)), 9, 1), "") -> W | U34: =IFERROR(IF(P34="","",COUNTIF(P34:T34,"W")*20+COUNTIF(P34:T34,"D")*7),"") -> 60 | W34: =COUNTIFS(Partite!$V:$V,1,Partite!$H:$H,Palinsesto!G34)+COUNTIFS(Partite!$V:$V,1,Partite!$J:$J,Palinsesto!G34) -> 5 | Y34: =INDEX(AC$4:AE$4, MATCH(MAX(AC34:AE34), AC34:AE34, 0)) -> 0-2 | Z34: =IFERROR(INT((LARGE(AC34:AE34,1)/SUM(H34:J34))*100),"") -> 81 | AA34: =COUNTIFS(Partite!$W:$W,1,Partite!$H:$H,Palinsesto!G34)+COUNTIFS(Partite!$W:$W,1,Partite!$J:$J,Palinsesto!G34) -> 9 | AC34: =COUNTIFS(Partite!$X:$X,1,Partite!$H:$H,Palinsesto!G34)+COUNTIFS(Partite!$X:$X,1,Partite!$J:$J,Palinsesto!G34) -> 9 | AD34: =COUNTIFS(Partite!$Y:$Y,1,Partite!$H:$H,Palinsesto!G34)+COUNTIFS(Partite!$Y:$Y,1,Partite!$J:$J,Palinsesto!G34) -> 8 | AE34: =COUNTIFS(Partite!$Z:$Z,1,Partite!$H:$H,Palinsesto!G34)+COUNTIFS(Partite!$Z:$Z,1,Partite!$J:$J,Palinsesto!G34) -> 6
B36: =B33+1 -> 11 | C36: =VLOOKUP($B$2+B36,Partite!$A$1:$AE$3000,2,FALSE) -> Allsvenskan | D36: =VLOOKUP($B$2+B36,Partite!$A$1:$AE$3000,4,FALSE) -> 14 | E36: =VLOOKUP($B$2+B36,Partite!$A$1:$AE$3000,6,FALSE) -> 46228 | F36: =VLOOKUP($B$2+B36,Partite!$A$1:$AE$3000,7,FALSE) -> 17:30 | G36: =VLOOKUP($B$2+B36,Partite!$A$1:$AE$3000,8,FALSE) -> Kalmar | H36: =IFERROR(VLOOKUP(G36,Classifica!$C$2:$R$131,3,FALSE),"") -> 4 | I36: =IFERROR(VLOOKUP(G36,Classifica!$C$2:$R$131,4,FALSE),"") -> 1 | J36: =IFERROR(VLOOKUP(G36,Classifica!$C$2:$R$131,5,FALSE),"") -> 7 | K36: =IFERROR(VLOOKUP(G36,Classifica!$C$2:$R$131,6,FALSE),"") -> 14 | L36: =IFERROR(VLOOKUP(G36,Classifica!$C$2:$R$131,7,FALSE),"") -> 17 | M36: =IFERROR(VLOOKUP(G36,Classifica!$C$2:$R$131,8,FALSE),"") -> -3 | N36: =IFERROR(VLOOKUP(G36,Classifica!$C$2:$R$131,9,FALSE),"") -> 13 | O36: =IFERROR(VLOOKUP(G36,Classifica!$C$2:$R$131,16,FALSE),"") -> 12 | P36: =IFERROR(MID(INDEX(Classifica!M:M, MATCH(G36, Classifica!C:C, 0)), 1, 1), "") -> L | Q36: =IFERROR(MID(INDEX(Classifica!M:M, MATCH(G36, Classifica!C:C, 0)), 3, 1), "") -> W | R36: =IFERROR(MID(INDEX(Classifica!M:M, MATCH(G36, Classifica!C:C, 0)), 5, 1), "") -> L | S36: =IFERROR(MID(INDEX(Classifica!M:M, MATCH(G36, Classifica!C:C, 0)), 7, 1), "") -> W | T36: =IFERROR(MID(INDEX(Classifica!M:M, MATCH(G36, Classifica!C:C, 0)), 9, 1), "") -> L | U36: =IFERROR(IF(P36="","",COUNTIF(P36:T36,"W")*20+COUNTIF(P36:T36,"D")*7),"") -> 40 | V36: =IFERROR(ABS(U36-U37),"") -> 12 | W36: =COUNTIFS(Partite!$V:$V,1,Partite!$H:$H,Palinsesto!G36)+COUNTIFS(Partite!$V:$V,1,Partite!$J:$J,Palinsesto!G36) -> 9 | X36: =IFERROR(AVERAGE(IFERROR(INT(W36/(SUM(H36:J36))*100),""),IFERROR(INT(W37/(SUM(H37:J37))*100),"")),"") -> 60.5 | Y36: =INDEX(AC$4:AE$4, MATCH(MAX(AC36:AE36), AC36:AE36, 0)) -> 1-3 | Z36: =IFERROR(INT((LARGE(AC36:AE36,1)/SUM(H36:J36))*100),"") -> 100 | AA36: =COUNTIFS(Partite!$W:$W,1,Partite!$H:$H,Palinsesto!G36)+COUNTIFS(Partite!$W:$W,1,Partite!$J:$J,Palinsesto!G36) -> 10 | AB36: =IFERROR(INT(AVERAGE(AA36/(SUM(H36:J36))*100,(AA37/(SUM(H37:J37))*100))),"") -> 80 | AC36: =COUNTIFS(Partite!$X:$X,1,Partite!$H:$H,Palinsesto!G36)+COUNTIFS(Partite!$X:$X,1,Partite!$J:$J,Palinsesto!G36) -> 9 | AD36: =COUNTIFS(Partite!$Y:$Y,1,Partite!$H:$H,Palinsesto!G36)+COUNTIFS(Partite!$Y:$Y,1,Partite!$J:$J,Palinsesto!G36) -> 12 | AE36: =COUNTIFS(Partite!$Z:$Z,1,Partite!$H:$H,Palinsesto!G36)+COUNTIFS(Partite!$Z:$Z,1,Partite!$J:$J,Palinsesto!G36) -> 9
G37: =VLOOKUP($B$2+B36,Partite!$A$1:$AE$3000,10,FALSE) -> Mjällby | H37: =IFERROR(VLOOKUP(G37,Classifica!$C$2:$R$131,3,FALSE),"") -> 4 | I37: =IFERROR(VLOOKUP(G37,Classifica!$C$2:$R$131,4,FALSE),"") -> 5 | J37: =IFERROR(VLOOKUP(G37,Classifica!$C$2:$R$131,5,FALSE),"") -> 4 | K37: =IFERROR(VLOOKUP(G37,Classifica!$C$2:$R$131,6,FALSE),"") -> 19 | L37: =IFERROR(VLOOKUP(G37,Classifica!$C$2:$R$131,7,FALSE),"") -> 17 | M37: =IFERROR(VLOOKUP(G37,Classifica!$C$2:$R$131,8,FALSE),"") -> 2 | N37: =IFERROR(VLOOKUP(G37,Classifica!$C$2:$R$131,9,FALSE),"") -> 17 | O37: =IFERROR(VLOOKUP(G37,Classifica!$C$2:$R$131,16,FALSE),"") -> 10 | P37: =IFERROR(MID(INDEX(Classifica!M:M, MATCH(G37, Classifica!C:C, 0)), 1, 1), "") -> D | Q37: =IFERROR(MID(INDEX(Classifica!M:M, MATCH(G37, Classifica!C:C, 0)), 3, 1), "") -> D | R37: =IFERROR(MID(INDEX(Classifica!M:M, MATCH(G37, Classifica!C:C, 0)), 5, 1), "") -> D | S37: =IFERROR(MID(INDEX(Classifica!M:M, MATCH(G37, Classifica!C:C, 0)), 7, 1), "") -> L | T37: =IFERROR(MID(INDEX(Classifica!M:M, MATCH(G37, Classifica!C:C, 0)), 9, 1), "") -> D | U37: =IFERROR(IF(P37="","",COUNTIF(P37:T37,"W")*20+COUNTIF(P37:T37,"D")*7),"") -> 28 | W37: =COUNTIFS(Partite!$V:$V,1,Partite!$H:$H,Palinsesto!G37)+COUNTIFS(Partite!$V:$V,1,Partite!$J:$J,Palinsesto!G37) -> 6 | Y37: =INDEX(AC$4:AE$4, MATCH(MAX(AC37:AE37), AC37:AE37, 0)) -> 0-2 | Z37: =IFERROR(INT((LARGE(AC37:AE37,1)/SUM(H37:J37))*100),"") -> 76 | AA37: =COUNTIFS(Partite!$W:$W,1,Partite!$H:$H,Palinsesto!G37)+COUNTIFS(Partite!$W:$W,1,Partite!$J:$J,Palinsesto!G37) -> 10 | AC37: =COUNTIFS(Partite!$X:$X,1,Partite!$H:$H,Palinsesto!G37)+COUNTIFS(Partite!$X:$X,1,Partite!$J:$J,Palinsesto!G37) -> 10 | AD37: =COUNTIFS(Partite!$Y:$Y,1,Partite!$H:$H,Palinsesto!G37)+COUNTIFS(Partite!$Y:$Y,1,Partite!$J:$J,Palinsesto!G37) -> 8 | AE37: =COUNTIFS(Partite!$Z:$Z,1,Partite!$H:$H,Palinsesto!G37)+COUNTIFS(Partite!$Z:$Z,1,Partite!$J:$J,Palinsesto!G37) -> 5
B39: =B36+1 -> 12 | C39: =VLOOKUP($B$2+B39,Partite!$A$1:$AE$3000,2,FALSE) -> Chinese | D39: =VLOOKUP($B$2+B39,Partite!$A$1:$AE$3000,4,FALSE) -> 20 | E39: =VLOOKUP($B$2+B39,Partite!$A$1:$AE$3000,6,FALSE) -> 46228 | F39: =VLOOKUP($B$2+B39,Partite!$A$1:$AE$3000,7,FALSE) -> 17:30 (11:30) | G39: =VLOOKUP($B$2+B39,Partite!$A$1:$AE$3000,8,FALSE) -> Qingdao Hainiu | H39: =IFERROR(VLOOKUP(G39,Classifica!$C$2:$R$131,3,FALSE),"") -> 6 | I39: =IFERROR(VLOOKUP(G39,Classifica!$C$2:$R$131,4,FALSE),"") -> 3 | J39: =IFERROR(VLOOKUP(G39,Classifica!$C$2:$R$131,5,FALSE),"") -> 10 | K39: =IFERROR(VLOOKUP(G39,Classifica!$C$2:$R$131,6,FALSE),"") -> 30 | L39: =IFERROR(VLOOKUP(G39,Classifica!$C$2:$R$131,7,FALSE),"") -> 36 | M39: =IFERROR(VLOOKUP(G39,Classifica!$C$2:$R$131,8,FALSE),"") -> -6 | N39: =IFERROR(VLOOKUP(G39,Classifica!$C$2:$R$131,9,FALSE),"") -> 21 | O39: =IFERROR(VLOOKUP(G39,Classifica!$C$2:$R$131,16,FALSE),"") -> 14 | P39: =IFERROR(MID(INDEX(Classifica!M:M, MATCH(G39, Classifica!C:C, 0)), 1, 1), "") -> L | Q39: =IFERROR(MID(INDEX(Classifica!M:M, MATCH(G39, Classifica!C:C, 0)), 3, 1), "") -> W | R39: =IFERROR(MID(INDEX(Classifica!M:M, MATCH(G39, Classifica!C:C, 0)), 5, 1), "") -> D | S39: =IFERROR(MID(INDEX(Classifica!M:M, MATCH(G39, Classifica!C:C, 0)), 7, 1), "") -> L | T39: =IFERROR(MID(INDEX(Classifica!M:M, MATCH(G39, Classifica!C:C, 0)), 9, 1), "") -> L | U39: =IFERROR(IF(P39="","",COUNTIF(P39:T39,"W")*20+COUNTIF(P39:T39,"D")*7),"") -> 27 | V39: =IFERROR(ABS(U39-U40),"") -> 40 | W39: =COUNTIFS(Partite!$V:$V,1,Partite!$H:$H,Palinsesto!G39)+COUNTIFS(Partite!$V:$V,1,Partite!$J:$J,Palinsesto!G39) -> 9 | X39: =IFERROR(AVERAGE(IFERROR(INT(W39/(SUM(H39:J39))*100),""),IFERROR(INT(W40/(SUM(H40:J40))*100),"")),"") -> 51 | Y39: =INDEX(AC$4:AE$4, MATCH(MAX(AC39:AE39), AC39:AE39, 0)) -> 1-3 | Z39: =IFERROR(INT((LARGE(AC39:AE39,1)/SUM(H39:J39))*100),"") -> 68 | AA39: =COUNTIFS(Partite!$W:$W,1,Partite!$H:$H,Palinsesto!G39)+COUNTIFS(Partite!$W:$W,1,Partite!$J:$J,Palinsesto!G39) -> 15 | AB39: =IFERROR(INT(AVERAGE(AA39/(SUM(H39:J39))*100,(AA40/(SUM(H40:J40))*100))),"") -> 78 | AC39: =COUNTIFS(Partite!$X:$X,1,Partite!$H:$H,Palinsesto!G39)+COUNTIFS(Partite!$X:$X,1,Partite!$J:$J,Palinsesto!G39) -> 10 | AD39: =COUNTIFS(Partite!$Y:$Y,1,Partite!$H:$H,Palinsesto!G39)+COUNTIFS(Partite!$Y:$Y,1,Partite!$J:$J,Palinsesto!G39) -> 13 | AE39: =COUNTIFS(Partite!$Z:$Z,1,Partite!$H:$H,Palinsesto!G39)+COUNTIFS(Partite!$Z:$Z,1,Partite!$J:$J,Palinsesto!G39) -> 11
G40: =VLOOKUP($B$2+B39,Partite!$A$1:$AE$3000,10,FALSE) -> Jinmen Tiger | H40: =IFERROR(VLOOKUP(G40,Classifica!$C$2:$R$131,3,FALSE),"") -> 5 | I40: =IFERROR(VLOOKUP(G40,Classifica!$C$2:$R$131,4,FALSE),"") -> 6 | J40: =IFERROR(VLOOKUP(G40,Classifica!$C$2:$R$131,5,FALSE),"") -> 7 | K40: =IFERROR(VLOOKUP(G40,Classifica!$C$2:$R$131,6,FALSE),"") -> 24 | L40: =IFERROR(VLOOKUP(G40,Classifica!$C$2:$R$131,7,FALSE),"") -> 22 | M40: =IFERROR(VLOOKUP(G40,Classifica!$C$2:$R$131,8,FALSE),"") -> 2 | N40: =IFERROR(VLOOKUP(G40,Classifica!$C$2:$R$131,9,FALSE),"") -> 21 | O40: =IFERROR(VLOOKUP(G40,Classifica!$C$2:$R$131,16,FALSE),"") -> 15 | P40: =IFERROR(MID(INDEX(Classifica!M:M, MATCH(G40, Classifica!C:C, 0)), 1, 1), "") -> D | Q40: =IFERROR(MID(INDEX(Classifica!M:M, MATCH(G40, Classifica!C:C, 0)), 3, 1), "") -> W | R40: =IFERROR(MID(INDEX(Classifica!M:M, MATCH(G40, Classifica!C:C, 0)), 5, 1), "") -> L | S40: =IFERROR(MID(INDEX(Classifica!M:M, MATCH(G40, Classifica!C:C, 0)), 7, 1), "") -> W | T40: =IFERROR(MID(INDEX(Classifica!M:M, MATCH(G40, Classifica!C:C, 0)), 9, 1), "") -> W | U40: =IFERROR(IF(P40="","",COUNTIF(P40:T40,"W")*20+COUNTIF(P40:T40,"D")*7),"") -> 67 | W40: =COUNTIFS(Partite!$V:$V,1,Partite!$H:$H,Palinsesto!G40)+COUNTIFS(Partite!$V:$V,1,Partite!$J:$J,Palinsesto!G40) -> 10 | Y40: =INDEX(AC$4:AE$4, MATCH(MAX(AC40:AE40), AC40:AE40, 0)) -> 0-2 | Z40: =IFERROR(INT((LARGE(AC40:AE40,1)/SUM(H40:J40))*100),"") -> 88 | AA40: =COUNTIFS(Partite!$W:$W,1,Partite!$H:$H,Palinsesto!G40)+COUNTIFS(Partite!$W:$W,1,Partite!$J:$J,Palinsesto!G40) -> 14 | AC40: =COUNTIFS(Partite!$X:$X,1,Partite!$H:$H,Palinsesto!G40)+COUNTIFS(Partite!$X:$X,1,Partite!$J:$J,Palinsesto!G40) -> 16 | AD40: =COUNTIFS(Partite!$Y:$Y,1,Partite!$H:$H,Palinsesto!G40)+COUNTIFS(Partite!$Y:$Y,1,Partite!$J:$J,Palinsesto!G40) -> 15 | AE40: =COUNTIFS(Partite!$Z:$Z,1,Partite!$H:$H,Palinsesto!G40)+COUNTIFS(Partite!$Z:$Z,1,Partite!$J:$J,Palinsesto!G40) -> 5
B42: =B39+1 -> 13 | C42: =VLOOKUP($B$2+B42,Partite!$A$1:$AE$3000,2,FALSE) -> Chinese | D42: =VLOOKUP($B$2+B42,Partite!$A$1:$AE$3000,4,FALSE) -> 20 | E42: =VLOOKUP($B$2+B42,Partite!$A$1:$AE$3000,6,FALSE) -> 46228 | F42: =VLOOKUP($B$2+B42,Partite!$A$1:$AE$3000,7,FALSE) -> 19:35 (13:35) | G42: =VLOOKUP($B$2+B42,Partite!$A$1:$AE$3000,8,FALSE) -> Shanghai Port | H42: =IFERROR(VLOOKUP(G42,Classifica!$C$2:$R$131,3,FALSE),"") -> 5 | I42: =IFERROR(VLOOKUP(G42,Classifica!$C$2:$R$131,4,FALSE),"") -> 6 | J42: =IFERROR(VLOOKUP(G42,Classifica!$C$2:$R$131,5,FALSE),"") -> 7 | K42: =IFERROR(VLOOKUP(G42,Classifica!$C$2:$R$131,6,FALSE),"") -> 28 | L42: =IFERROR(VLOOKUP(G42,Classifica!$C$2:$R$131,7,FALSE),"") -> 26 | M42: =IFERROR(VLOOKUP(G42,Classifica!$C$2:$R$131,8,FALSE),"") -> 2 | N42: =IFERROR(VLOOKUP(G42,Classifica!$C$2:$R$131,9,FALSE),"") -> 21 | O42: =IFERROR(VLOOKUP(G42,Classifica!$C$2:$R$131,16,FALSE),"") -> 13 | P42: =IFERROR(MID(INDEX(Classifica!M:M, MATCH(G42, Classifica!C:C, 0)), 1, 1), "") -> D | Q42: =IFERROR(MID(INDEX(Classifica!M:M, MATCH(G42, Classifica!C:C, 0)), 3, 1), "") -> L | R42: =IFERROR(MID(INDEX(Classifica!M:M, MATCH(G42, Classifica!C:C, 0)), 5, 1), "") -> W | S42: =IFERROR(MID(INDEX(Classifica!M:M, MATCH(G42, Classifica!C:C, 0)), 7, 1), "") -> L | T42: =IFERROR(MID(INDEX(Classifica!M:M, MATCH(G42, Classifica!C:C, 0)), 9, 1), "") -> D | U42: =IFERROR(IF(P42="","",COUNTIF(P42:T42,"W")*20+COUNTIF(P42:T42,"D")*7),"") -> 34 | V42: =IFERROR(ABS(U42-U43),"") -> 13 | W42: =COUNTIFS(Partite!$V:$V,1,Partite!$H:$H,Palinsesto!G42)+COUNTIFS(Partite!$V:$V,1,Partite!$J:$J,Palinsesto!G42) -> 10 | X42: =IFERROR(AVERAGE(IFERROR(INT(W42/(SUM(H42:J42))*100),""),IFERROR(INT(W43/(SUM(H43:J43))*100),"")),"") -> 46.5 | Y42: =INDEX(AC$4:AE$4, MATCH(MAX(AC42:AE42), AC42:AE42, 0)) -> 1-3 | Z42: =IFERROR(INT((LARGE(AC42:AE42,1)/SUM(H42:J42))*100),"") -> 83 | AA42: =COUNTIFS(Partite!$W:$W,1,Partite!$H:$H,Palinsesto!G42)+COUNTIFS(Partite!$W:$W,1,Partite!$J:$J,Palinsesto!G42) -> 15 | AB42: =IFERROR(INT(AVERAGE(AA42/(SUM(H42:J42))*100,(AA43/(SUM(H43:J43))*100))),"") -> 86 | AC42: =COUNTIFS(Partite!$X:$X,1,Partite!$H:$H,Palinsesto!G42)+COUNTIFS(Partite!$X:$X,1,Partite!$J:$J,Palinsesto!G42) -> 14 | AD42: =COUNTIFS(Partite!$Y:$Y,1,Partite!$H:$H,Palinsesto!G42)+COUNTIFS(Partite!$Y:$Y,1,Partite!$J:$J,Palinsesto!G42) -> 15 | AE42: =COUNTIFS(Partite!$Z:$Z,1,Partite!$H:$H,Palinsesto!G42)+COUNTIFS(Partite!$Z:$Z,1,Partite!$J:$J,Palinsesto!G42) -> 9
G43: =VLOOKUP($B$2+B42,Partite!$A$1:$AE$3000,10,FALSE) -> Shanghai Shen | H43: =IFERROR(VLOOKUP(G43,Classifica!$C$2:$R$131,3,FALSE),"") -> 8 | I43: =IFERROR(VLOOKUP(G43,Classifica!$C$2:$R$131,4,FALSE),"") -> 5 | J43: =IFERROR(VLOOKUP(G43,Classifica!$C$2:$R$131,5,FALSE),"") -> 5 | K43: =IFERROR(VLOOKUP(G43,Classifica!$C$2:$R$131,6,FALSE),"") -> 36 | L43: =IFERROR(VLOOKUP(G43,Classifica!$C$2:$R$131,7,FALSE),"") -> 29 | M43: =IFERROR(VLOOKUP(G43,Classifica!$C$2:$R$131,8,FALSE),"") -> 7 | N43: =IFERROR(VLOOKUP(G43,Classifica!$C$2:$R$131,9,FALSE),"") -> 29 | O43: =IFERROR(VLOOKUP(G43,Classifica!$C$2:$R$131,16,FALSE),"") -> 11 | P43: =IFERROR(MID(INDEX(Classifica!M:M, MATCH(G43, Classifica!C:C, 0)), 1, 1), "") -> L | Q43: =IFERROR(MID(INDEX(Classifica!M:M, MATCH(G43, Classifica!C:C, 0)), 3, 1), "") -> D | R43: =IFERROR(MID(INDEX(Classifica!M:M, MATCH(G43, Classifica!C:C, 0)), 5, 1), "") -> W | S43: =IFERROR(MID(INDEX(Classifica!M:M, MATCH(G43, Classifica!C:C, 0)), 7, 1), "") -> W | T43: =IFERROR(MID(INDEX(Classifica!M:M, MATCH(G43, Classifica!C:C, 0)), 9, 1), "") -> L | U43: =IFERROR(IF(P43="","",COUNTIF(P43:T43,"W")*20+COUNTIF(P43:T43,"D")*7),"") -> 47 | W43: =COUNTIFS(Partite!$V:$V,1,Partite!$H:$H,Palinsesto!G43)+COUNTIFS(Partite!$V:$V,1,Partite!$J:$J,Palinsesto!G43) -> 7 | Y43: =INDEX(AC$4:AE$4, MATCH(MAX(AC43:AE43), AC43:AE43, 0)) -> 0-2 | Z43: =IFERROR(INT((LARGE(AC43:AE43,1)/SUM(H43:J43))*100),"") -> 77 | AA43: =COUNTIFS(Partite!$W:$W,1,Partite!$H:$H,Palinsesto!G43)+COUNTIFS(Partite!$W:$W,1,Partite!$J:$J,Palinsesto!G43) -> 16 | AC43: =COUNTIFS(Partite!$X:$X,1,Partite!$H:$H,Palinsesto!G43)+COUNTIFS(Partite!$X:$X,1,Partite!$J:$J,Palinsesto!G43) -> 14 | AD43: =COUNTIFS(Partite!$Y:$Y,1,Partite!$H:$H,Palinsesto!G43)+COUNTIFS(Partite!$Y:$Y,1,Partite!$J:$J,Palinsesto!G43) -> 14 | AE43: =COUNTIFS(Partite!$Z:$Z,1,Partite!$H:$H,Palinsesto!G43)+COUNTIFS(Partite!$Z:$Z,1,Partite!$J:$J,Palinsesto!G43) -> 10
B45: =B42+1 -> 14 | C45: =VLOOKUP($B$2+B45,Partite!$A$1:$AE$3000,2,FALSE) -> Chinese | D45: =VLOOKUP($B$2+B45,Partite!$A$1:$AE$3000,4,FALSE) -> 20 | E45: =VLOOKUP($B$2+B45,Partite!$A$1:$AE$3000,6,FALSE) -> 46228 | F45: =VLOOKUP($B$2+B45,Partite!$A$1:$AE$3000,7,FALSE) -> 19:35 (13:35) | G45: =VLOOKUP($B$2+B45,Partite!$A$1:$AE$3000,8,FALSE) -> Shenyang Urban | H45: =IFERROR(VLOOKUP(G45,Classifica!$C$2:$R$131,3,FALSE),"") -> 6 | I45: =IFERROR(VLOOKUP(G45,Classifica!$C$2:$R$131,4,FALSE),"") -> 3 | J45: =IFERROR(VLOOKUP(G45,Classifica!$C$2:$R$131,5,FALSE),"") -> 9 | K45: =IFERROR(VLOOKUP(G45,Classifica!$C$2:$R$131,6,FALSE),"") -> 25 | L45: =IFERROR(VLOOKUP(G45,Classifica!$C$2:$R$131,7,FALSE),"") -> 30 | M45: =IFERROR(VLOOKUP(G45,Classifica!$C$2:$R$131,8,FALSE),"") -> -5 | N45: =IFERROR(VLOOKUP(G45,Classifica!$C$2:$R$131,9,FALSE),"") -> 21 | O45: =IFERROR(VLOOKUP(G45,Classifica!$C$2:$R$131,16,FALSE),"") -> 8 | P45: =IFERROR(MID(INDEX(Classifica!M:M, MATCH(G45, Classifica!C:C, 0)), 1, 1), "") -> W | Q45: =IFERROR(MID(INDEX(Classifica!M:M, MATCH(G45, Classifica!C:C, 0)), 3, 1), "") -> W | R45: =IFERROR(MID(INDEX(Classifica!M:M, MATCH(G45, Classifica!C:C, 0)), 5, 1), "") -> L | S45: =IFERROR(MID(INDEX(Classifica!M:M, MATCH(G45, Classifica!C:C, 0)), 7, 1), "") -> W | T45: =IFERROR(MID(INDEX(Classifica!M:M, MATCH(G45, Classifica!C:C, 0)), 9, 1), "") -> D | U45: =IFERROR(IF(P45="","",COUNTIF(P45:T45,"W")*20+COUNTIF(P45:T45,"D")*7),"") -> 67 | V45: =IFERROR(ABS(U45-U46),"") -> 13 | W45: =COUNTIFS(Partite!$V:$V,1,Partite!$H:$H,Palinsesto!G45)+COUNTIFS(Partite!$V:$V,1,Partite!$J:$J,Palinsesto!G45) -> 12 | X45: =IFERROR(AVERAGE(IFERROR(INT(W45/(SUM(H45:J45))*100),""),IFERROR(INT(W46/(SUM(H46:J46))*100),"")),"") -> 46 | Y45: =INDEX(AC$4:AE$4, MATCH(MAX(AC45:AE45), AC45:AE45, 0)) -> 1-3 | Z45: =IFERROR(INT((LARGE(AC45:AE45,1)/SUM(H45:J45))*100),"") -> 77 | AA45: =COUNTIFS(Partite!$W:$W,1,Partite!$H:$H,Palinsesto!G45)+COUNTIFS(Partite!$W:$W,1,Partite!$J:$J,Palinsesto!G45) -> 14 | AB45: =IFERROR(INT(AVERAGE(AA45/(SUM(H45:J45))*100,(AA46/(SUM(H46:J46))*100))),"") -> 80 | AC45: =COUNTIFS(Partite!$X:$X,1,Partite!$H:$H,Palinsesto!G45)+COUNTIFS(Partite!$X:$X,1,Partite!$J:$J,Palinsesto!G45) -> 12 | AD45: =COUNTIFS(Partite!$Y:$Y,1,Partite!$H:$H,Palinsesto!G45)+COUNTIFS(Partite!$Y:$Y,1,Partite!$J:$J,Palinsesto!G45) -> 14 | AE45: =COUNTIFS(Partite!$Z:$Z,1,Partite!$H:$H,Palinsesto!G45)+COUNTIFS(Partite!$Z:$Z,1,Partite!$J:$J,Palinsesto!G45) -> 9
